Workbook

Sheet Commercial
A1: Rep # | B1: Rep Name | C1: Monday | D1: Tuesday | E1: Wednesday | F1: Thursday | G1: Friday | H1: Total COMP | I1: BAD TPV | J1: TOTAL WK | K1: Last Week | L1: Difference | M1: Program | N1: Manager | O1: MWH Total
B2: Fronters
A3: 1291 | B3: Raven Mitchell (Commercial) | H3: =SUM(C3:G3) -> 0 | J3: =H3-I3 -> 0 | K3: 4 | L3: =H3-K3 -> -4 | M3: ELIGO | N3: CJ
A4: 1292 | B4: Jakarta Hunter (Commercial) | C4: 1 | H4: =SUM(C4:G4) -> 1 | J4: =H4-I4 -> 1 | K4: 1 | L4: =H4-K4 -> 0 | M4: ELIGO | N4: CJ
A5: 1295 | B5: Luis Buitrago (Commercial) | H5: =SUM(C5:G5) -> 0 | J5: =H5-I5 -> 0 | K5: 1 | L5: =H5-K5 -> -1 | M5: ELIGO | N5: CJ
A6: 1290 | B6: Abigail Gambino (Commercial-Closer) | H6: =SUM(C6:G6) -> 0 | J6: =H6-I6 -> 0 | K6: 0 | L6: =H6-K6 -> 0 | M6: ELIGO | N6: CJ
A7: 1288 | B7: Allen Alberts(Commercial-Closer) | H7: =SUM(C7:G7) -> 0 | J7: =H7-I7 -> 0 | K7: 4 | L7: =H7-K7 -> -4 | M7: ELIGO | N7: CJ
A8: 1175 | B8: Kenticka Tate (Remote)(Commercial) | C8: 2 | H8: =SUM(C8:G8) -> 2 | J8: =H8-I8 -> 2 | K8: 4 | L8: =H8-K8 -> -2 | M8: ELIGO | N8: CJ
A9: 1294 | B9: Brandy Paton (Commercial) | H9: =SUM(C9:G9) -> 0 | J9: =H9-I9 -> 0 | K9: 1 | L9: =H9-K9 -> -1 | M9: ELIGO | N9: CJ
A10: 1280 | B10: Ashlee Franks (Commercial) | H10: =SUM(C10:G10) -> 0 | J10: =H10-I10 -> 0 | K10: 0 | L10: =H10-K10 -> 0 | M10: ELIGO | N10: CJ
A11: 1298 | B11: Shelby Lewis (Commercial) | H11: =SUM(C11:G11) -> 0 | J11: =H11-I11 -> 0 | K11: 1 | L11: =H11-K11 -> -1 | M11: ELIGO | N11: CJ
A12: 1300 | B12: Neil Singhal (Commercial) | H12: =SUM(C12:G12) -> 0 | J12: =H12-I12 -> 0 | K12: 3 | L12: =H12-K12 -> -3 | M12: ELIGO | N12: CJ
A13: 1301 | B13: Albert Williams (Commercial) | H13: =SUM(C13:G13) -> 0 | J13: =H13-I13 -> 0 | K13: 1 | L13: =H13-K13 -> -1 | M13: ELIGO | N13: CJ
H14: =SUM(C14:G14) -> 0 | J14: =H14-I14 -> 0 | L14: =H14-K14 -> 0 | M14: ELIGO | N14: CJ
H15: =SUM(C15:G15) -> 0 | J15: =H15-I15 -> 0 | L15: =H15-K15 -> 0 | M15: ELIGO | N15: CJ
B16: Total | C16: =SUM(C3:C15) -> 3 | D16: =SUM(D3:D15) -> 0 | E16: =SUM(E3:E15) -> 0 | F16: =SUM(F3:F15) -> 0 | G16: =SUM(G3:G15) -> 0 | H16: =SUM(C16:G16) -> 3 | J16: =H16-I16 -> 3 | K16: 23 | L16: =H16-K16 -> -20 | M16: ELIGO | N16: CJ
B17: Closers
A18: Rep # | B18: Rep Name | C18: Monday | D18: Tuesday | E18: Wednesday | F18: Thursday | G18: Friday | H18: Total COMP | I18: BAD TPV | J18: TOTAL WK | K18: Last Week | L18: Difference | M18: Program | N18: Manager
A19: 1290 | B19: Abigail Gambino (Commercial-Closer) | H19: =SUM(C19:G19) -> 0 | J19: =H19-I19 -> 0 | K19: 5 | L19: =H19-K19 -> -5 | M19: ELIGO | N19: CJ
A20: 1288 | B20: Allen Alberts(Commercial-Closer) | H20: =SUM(C20:G20) -> 0 | J20: =H20-I20 -> 0 | K20: 4 | L20: =H20-K20 -> -4 | M20: ELIGO | N20: CJ
A21: 1151 | B21: CJ Jackson (Manager/Closer) | H21: =SUM(C21:G21) -> 0 | J21: =H21-I21 -> 0 | K21: 0 | L21: =H21-K21 -> 0 | M21: ELIGO | N21: CJ
A22: 1294 | B22: Brandy Paton (Commercial-Closer) | H22: =SUM(C22:G22) -> 0 | J22: =H22-I22 -> 0 | K22: 1 | L22: =H22-K22 -> -1 | M22: ELIGO | N22: CJ
A23: 1300 | B23: Neil Singhal (Commercial) | C23: 2 | H23: =SUM(C23:G23) -> 2 | J23: =H23-I23 -> 2 | K23: 5 | L23: =H23-K23 -> -3 | M23: ELIGO | N23: CJ
H24: =SUM(C24:G24) -> 0 | J24: =H24-I24 -> 0 | L24: =H24-K24 -> 0 | M24: ELIGO | N24: CJ
B25: Total | C25: =SUM(C19:C24) -> 2 | D25: =SUM(D19:D24) -> 0 | E25: =SUM(E19:E24) -> 0 | F25: =SUM(F19:F24) -> 0 | G25: =SUM(G19:G24) -> 0 | H25: =SUM(C25:G25) -> 2 | J25: =H25-I25 -> 2 | K25: 15 | L25: =H25-K25 -> -13 | M25: ELIGO | N25: CJ
B26: TRAINING (in house)
A27: Rep # | B27: Rep Name | C27: Monday | D27: Tuesday | E27: Wednesday | F27: Thursday | G27: Friday | H27: Total COMP | I27: BAD TPV | J27: TOTAL WK | K27: Last Week | L27: Difference | M27: Program | N27: Manager
H28: =SUM(C28:G28) -> 0 | J28: =H28-I28 -> 0 | K28: 0 | L28: =H28-K28 -> 0 | M28: ELIGO | N28: CJ
H29: =SUM(C29:G29) -> 0 | J29: =H29-I29 -> 0 | K29: 0 | L29: =H29-K29 -> 0 | M29: ELIGO | N29: CJ
H30: =SUM(C30:G30) -> 0 | J30: =H30-I30 -> 0 | K30: 0 | L30: =H30-K30 -> 0 | M30: ELIGO | N30: CJ
B31: Total | C31: =SUM(C28:C29) -> 0 | D31: =SUM(D28:D29) -> 0 | E31: =SUM(E28:E29) -> 0 | F31: =SUM(F28:F29) -> 0 | G31: =SUM(G28:G29) -> 0 | H31: =SUM(H28:H29) -> 0 | I31: =SUM(I28:I29) -> 0 | J31: =SUM(J28:J29) -> 0 | K31: =SUM(K28:K29) -> 0 | L31: =H31-K31 -> 0 | M31: ELIGO | N31: CJ
B32: Admin Staff
H33: =SUM(C33:G33) -> 0 | J33: =H33-I33 -> 0 | K33: 0 | L33: =H33-K33 -> 0 | M33: ELIGO | N33: CJ
H34: =SUM(C34:G34) -> 0 | J34: =H34-I34 -> 0 | K34: 0 | L34: =H34-K34 -> 0 | M34: ELIGO | N34: CJ
H35: =SUM(C35:G35) -> 0 | J35: =H35-I35 -> 0 | K35: 0 | L35: =H35-K35 -> 0 | M35: ELIGO | N35: CJ
H36: =SUM(C36:G36) -> 0 | J36: =H36-I36 -> 0 | K36: 0 | L36: =H36-K36 -> 0 | M36: ELIGO | N36: CJ
B37: Total | C37: =+SUM(C16,C25) -> 5 | D37: =+SUM(D16,D25) -> 0 | E37: =+SUM(E16,E25) -> 0 | F37: =+SUM(F16,F25) -> 0 | G37: =+SUM(G16,G25) -> 0 | H37: =+SUM(H16,H25) -> 5 | I37: =+SUM(I16) -> 0 | J37: =+SUM(J16) -> 3 | K37: =+SUM(K16) -> 23 | L37: =H37-K37 -> -18
B38: Last Week | C38: 2 | D38: 1 | E38: 2 | F38: 2 | G38: 0 | H38: 7
B39: Difference | C39: =C37-C38 -> 3 | D39: =D37-D38 -> -1 | E39: =E37-E38 -> -2 | F39: =F37-F38 -> -2 | G39: =G37-G38 -> 0 | H39: =H37-H38 -> -2

Sheet COM Winbacks
A1: Rep # | B1: Rep Name | C1: Monday | D1: Tuesday | E1: Wednesday | F1: Thursday | G1: Friday | H1: Nights | I1: Saturday | J1: Total COMP | K1: BAD TPV | L1: TOTAL WK | M1: Last Week | N1: Difference | O1: Program | P1: Manager
A2: IN HOUSE AGENTS
J3: =SUM(C3:I3) -> 0 | L3: =J3-K3 -> 0 | M3: 0 | N3: =J3-M3 -> 0 | O3: ELIGO | P3: CJ
J4: =SUM(C4:I4) -> 0 | L4: =J4-K4 -> 0 | M4: 0 | N4: =J4-M4 -> 0 | O4: ELIGO | P4: CJ
J5: =SUM(C5:I5) -> 0 | L5: =J5-K5 -> 0 | M5: 0 | N5: =J5-M5 -> 0 | O5: ELIGO | P5: CJ
J6: =SUM(C6:I6) -> 0 | L6: =J6-K6 -> 0 | M6: 0 | N6: =J6-M6 -> 0 | O6: ELIGO | P6: CJ
J7: =SUM(C7:I7) -> 0 | L7: =J7-K7 -> 0 | M7: 0 | N7: =J7-M7 -> 0 | O7: ELIGO | P7: CJ
J8: =SUM(C8:I8) -> 0 | L8: =J8-K8 -> 0 | M8: 0 | N8: =J8-M8 -> 0 | O8: ELIGO | P8: CJ
J9: =SUM(C9:I9) -> 0 | L9: =J9-K9 -> 0 | M9: 0 | N9: =J9-M9 -> 0 | O9: ELIGO | P9: CJ
J10: =SUM(C10:I10) -> 0 | L10: =J10-K10 -> 0 | M10: 0 | N10: =J10-M10 -> 0 | O10: ELIGO | P10: CJ
B11: Total | C11: =SUM(C3) -> 0 | D11: =SUM(D3) -> 0 | E11: =SUM(E3) -> 0 | F11: =SUM(F3) -> 0 | G11: =SUM(G3) -> 0 | H11: =SUM(H3) -> 0 | I11: =SUM(I3) -> 0 | J11: =SUM(J3:J10) -> 0 | K11: =SUM(K3) -> 0 | L11: =SUM(L3:L10) -> 0 | M11: =SUM(M3:M10) -> 0 | N11: =J11-M11 -> 0 | O11: ELIGO | P11: CJ
B12: Night Shift
A13: Rep # | B13: Rep Name | C13: Monday | D13: Tuesday | E13: Wednesday | F13: Thursday | G13: Friday | H13: Nights | I13: Saturday | J13: Total COMP | K13: BAD TPV | L13: TOTAL WK | M13: Last Week | N13: Difference | O13: Program | P13: Manager
J14: =SUM(C14:I14) -> 0 | L14: =J14-K14 -> 0 | M14: 0 | N14: =J14-M14 -> 0 | O14: ELIGO | P14: CJ
J15: =SUM(C15:I15) -> 0 | L15: =J15-K15 -> 0 | M15: 0 | N15: =J15-M15 -> 0 | O15: ELIGO | P15: CJ
J16: =SUM(C16:I16) -> 0 | L16: =J16-K16 -> 0 | M16: 0 | N16: =J16-M16 -> 0 | O16: ELIGO | P16: CJ
J17: =SUM(C17:I17) -> 0 | L17: =J17-K17 -> 0 | M17: 0 | N17: =J17-M17 -> 0 | O17: ELIGO | P17: CJ
J18: =SUM(C18:I18) -> 0 | L18: =J18-K18 -> 0 | M18: 0 | N18: =J18-M18 -> 0 | O18: ELIGO | P18: CJ
B19: Total | C19: =SUM(C14:C17) -> 0 | D19: =SUM(D14:D17) -> 0 | E19: =SUM(E14:E17) -> 0 | F19: =SUM(F14:F17) -> 0 | G19: =SUM(G14:G17) -> 0 | H19: =SUM(H14:H17) -> 0 | I19: =SUM(I14:I17) -> 0 | J19: =SUM(J14:J17) -> 0 | ... M19: =SUM(M14:M17) -> 0 | N19: =J19-M19 -> 0 | O19: ELIGO | P19: CJ
B20: TRAINING (in house)
A21: Rep # | B21: Rep Name | C21: Monday | D21: Tuesday | E21: Wednesday | F21: Thursday | G21: Friday | H21: Nights | I21: Saturday | J21: Total COMP | K21: BAD TPV | L21: TOTAL WK | M21: Last Week | N21: Difference | O21: Program | P21: Manager
J22: =SUM(C22:I22) -> 0 | L22: =J22-K22 -> 0 | M22: 0 | N22: =J22-M22 -> 0 | O22: ELIGO | P22: CJ
J23: =SUM(C23:I23) -> 0 | L23: =J23-K23 -> 0 | M23: 0 | N23: =J23-M23 -> 0 | O23: ELIGO | P23: CJ
J24: =SUM(C24:I24) -> 0 | L24: =J24-K24 -> 0 | M24: 0 | N24: =J24-M24 -> 0 | O24: ELIGO | P24: CJ
B25: Total | C25: =SUM(C22:C23) -> 0 | D25: =SUM(D22:D23) -> 0 | E25: =SUM(E22:E23) -> 0 | F25: =SUM(F22:F23) -> 0 | G25: =SUM(G22:G23) -> 0 | H25: =SUM(H22:H23) -> 0 | I25: =SUM(I22:I23) -> 0 | J25: =SUM(J22:J23) -> 0 | ... M25: =SUM(M22:M23) -> 0 | N25: =J25-M25 -> 0 | O25: ELIGO | P25: CJ
B26: Admin Staff
J27: =SUM(C27:I27) -> 0 | L27: =J27-K27 -> 0 | M27: 0 | N27: =J27-M27 -> 0 | O27: ELIGO | P27: CJ
J28: =SUM(C28:I28) -> 0 | L28: =J28-K28 -> 0 | M28: 0 | N28: =J28-M28 -> 0 | O28: ELIGO | P28: CJ
J29: =SUM(C29:I29) -> 0 | L29: =J29-K29 -> 0 | M29: 0 | N29: =J29-M29 -> 0 | O29: ELIGO | P29: CJ
J30: =SUM(C30:I30) -> 0 | L30: =J30-K30 -> 0 | M30: 0 | N30: =J30-M30 -> 0 | O30: ELIGO | P30: CJ
B31: Total | C31: =SUM(C11,C19,C25) -> 0 | D31: =SUM(D11,D19,D25) -> 0 | E31: =SUM(E11,E19,E25) -> 0 | F31: =SUM(F11,F19,F25) -> 0 | G31: =SUM(G11,G19,G25) -> 0 | H31: =SUM(H11,H19,H25) -> 0 | J31: =SUM(J11,J19,J25) -> 0 | K31: =SUM(K11,K19,K25) -> 0 | L31: =SUM(L11,L19,L25) -> 0 | M31: =SUM(M11,M19,M25) -> 0 | N31: =J31-M31 -> 0
B32: Last Week | C32: 0 | D32: 0 | E32: 0 | F32: 0 | G32: 0 | H32: 0 | J32: 0
B33: Difference | C33: =C31-C32 -> 0 | D33: =D31-D32 -> 0 | E33: =E31-E32 -> 0 | F33: =F31-F32 -> 0 | G33: =G31-G32 -> 0 | H33: =H31-H32 -> 0 | J33: =J31-J32 -> 0

Sheet Residential
A1: Rep # | B1: Rep Name | C1: Monday | D1: Tuesday | E1: Wednesday | F1: Thursday | G1: Friday | H1: Total COMP | I1: BAD TPV | J1: TOTAL WK | K1: Last Week | L1: Difference | M1: Program | N1: Manager
A2: IN HOUSE AGENTS
A3: 1290 | B3: Abigail Gambino (Commercial-Closer) | H3: =SUM(C3:G3) -> 0 | J3: =H3-I3 -> 0 | K3: 0 | L3: =H3-K3 -> 0 | M3: ELIGO | N3: CJ
A4: 1301 | B4: Albert Williams (Commercial) | H4: =SUM(C4:G4) -> 0 | J4: =H4-I4 -> 0 | K4: 0 | L4: =H4-K4 -> 0 | M4: ELIGO | N4: CJ
A5: 1288 | B5: Allen Alberts(Commercial-Closer) | H5: =SUM(C5:G5) -> 0 | J5: =H5-I5 -> 0 | K5: 0 | L5: =H5-K5 -> 0 | M5: ELIGO | N5: CJ
A6: 1280 | B6: Ashlee Franks (Commercial) | H6: =SUM(C6:G6) -> 0 | J6: =H6-I6 -> 0 | K6: 0 | L6: =H6-K6 -> 0 | M6: ELIGO | N6: CJ
A7: 1294 | B7: Brandy Paton (Commercial) | H7: =SUM(C7:G7) -> 0 | J7: =H7-I7 -> 0 | K7: 0 | L7: =H7-K7 -> 0 | M7: ELIGO | N7: CJ
A8: 1292 | B8: Jakarta Hunter (Commercial) | H8: =SUM(C8:G8) -> 0 | J8: =H8-I8 -> 0 | K8: 0 | L8: =H8-K8 -> 0 | M8: ELIGO | N8: CJ
A9: 1175 | B9: Kenticka Tate (Remote)(Commercial) | H9: =SUM(C9:G9) -> 0 | J9: =H9-I9 -> 0 | K9: 0 | L9: =H9-K9 -> 0 | M9: ELIGO | N9: CJ
A10: 1295 | B10: Luis Buitrago (Commercial) | H10: =SUM(C10:G10) -> 0 | J10: =H10-I10 -> 0 | K10: 0 | L10: =H10-K10 -> 0 | M10: ELIGO | N10: CJ
A11: 1300 | B11: Neil Singhal (Commercial) | H11: =SUM(C11:G11) -> 0 | J11: =H11-I11 -> 0 | K11: 0 | L11: =H11-K11 -> 0 | M11: ELIGO | N11: CJ
A12: 1291 | B12: Raven Mitchell (Commercial) | H12: =SUM(C12:G12) -> 0 | J12: =H12-I12 -> 0 | K12: 0 | L12: =H12-K12 -> 0 | M12: ELIGO | N12: CJ
A13: 1220 | B13: Sara Milanese (Commercial) | H13: =SUM(C13:G13) -> 0 | J13: =H13-I13 -> 0 | K13: 0 | L13: =H13-K13 -> 0 | M13: ELIGO | N13: CJ
A14: 1298 | B14: Shelby Lewis (Commercial) | H14: =SUM(C14:G14) -> 0 | J14: =H14-I14 -> 0 | K14: 0 | L14: =H14-K14 -> 0 | M14: ELIGO | N14: CJ
H15: =SUM(C15:G15) -> 0 | J15: =H15-I15 -> 0 | K15: 0 | L15: =H15-K15 -> 0 | M15: ELIGO | N15: CJ
H16: =SUM(C16:G16) -> 0 | J16: =H16-I16 -> 0 | K16: 0 | L16: =H16-K16 -> 0 | M16: ELIGO | N16: CJ
B17: Total | C17: =SUM(C3:C16) -> 0 | D17: =SUM(D3:D16) -> 0 | E17: =SUM(E3:E16) -> 0 | F17: =SUM(F3:F16) -> 0 | G17: =SUM(G3:G16) -> 0 | H17: =SUM(C17:G17) -> 0 | K17: =SUM(K3:K16) -> 0 | M17: ELIGO | N17: CJ
B18: Night Shift
A19: Rep # | B19: Rep Name | C19: Monday | D19: Tuesday | E19: Wednesday | F19: Thursday | G19: Friday | H19: Total COMP | I19: BAD TPV | J19: TOTAL WK | K19: Last Week | L19: Difference | M19: Program | N19: Manager
H20: =SUM(C20:G20) -> 0 | J20: =H20-I20 -> 0 | K20: 0 | L20: =H20-K20 -> 0 | M20: ELIGO | N20: CJ
H21: =SUM(C21:G21) -> 0 | J21: =H21-I21 -> 0 | K21: 0 | L21: =H21-K21 -> 0 | M21: ELIGO | N21: CJ
H22: =SUM(C22:G22) -> 0 | J22: =H22-I22 -> 0 | K22: 0 | L22: =H22-K22 -> 0 | M22: ELIGO | N22: CJ
H23: =SUM(C23:G23) -> 0 | J23: =H23-I23 -> 0 | K23: 0 | L23: =H23-K23 -> 0 | M23: ELIGO | N23: CJ
H24: =SUM(C24:G24) -> 0 | J24: =H24-I24 -> 0 | K24: 0 | L24: =H24-K24 -> 0 | M24: ELIGO | N24: CJ
H25: =SUM(C25:G25) -> 0 | J25: =H25-I25 -> 0 | K25: 0 | L25: =H25-K25 -> 0 | M25: ELIGO | N25: CJ
H26: =SUM(C26:G26) -> 0 | J26: =H26-I26 -> 0 | K26: 0 | L26: =H26-K26 -> 0 | M26: ELIGO | N26: CJ
H27: =SUM(C27:G27) -> 0 | J27: =H27-I27 -> 0 | K27: 0 | L27: =H27-K27 -> 0 | M27: ELIGO | N27: CJ
H28: =SUM(C28:G28) -> 0 | J28: =H28-I28 -> 0 | K28: 0 | L28: =H28-K28 -> 0 | M28: ELIGO | N28: CJ
H29: =SUM(C29:G29) -> 0 | J29: =H29-I29 -> 0 | K29: 0 | L29: =H29-K29 -> 0 | M29: ELIGO | N29: CJ
B30: Total | C30: =SUM(C20:C23) -> 0 | D30: =SUM(D20:D23) -> 0 | E30: =SUM(E20:E23) -> 0 | F30: =SUM(F20:F23) -> 0 | G30: =SUM(G20:G23) -> 0 | H30: =SUM(H20:H29) -> 0 | I30: =SUM(I20:I23) -> 0 | J30: =SUM(J20:J29) -> 0 | K30: =SUM(K20) -> 0 | L30: =H30-K30 -> 0 | M30: ELIGO | N30: CJ
B31: TRAINING (in house)
A32: Rep # | B32: Rep Name | C32: Monday | D32: Tuesday | E32: Wednesday | F32: Thursday | G32: Friday | H32: Total COMP | I32: BAD TPV | J32: TOTAL WK | K32: Last Week | L32: Difference | M32: Program | N32: Manager
H33: =SUM(C33:G33) -> 0 | J33: =H33-I33 -> 0 | K33: 0 | L33: =H33-K33 -> 0 | M33: ELIGO | N33: CJ
H34: =SUM(C34:G34) -> 0 | J34: =H34-I34 -> 0 | K34: 0 | L34: =H34-K34 -> 0 | M34: ELIGO | N34: CJ
H35: =SUM(C35:G35) -> 0 | J35: =H35-I35 -> 0 | K35: 0 | L35: =H35-K35 -> 0 | M35: ELIGO | N35: CJ
H36: =SUM(C36:G36) -> 0 | J36: =H36-I36 -> 0 | K36: 0 | L36: =H36-K36 -> 0 | M36: ELIGO | N36: CJ
B37: Admin Staff
H38: =SUM(C38:G38) -> 0 | J38: =H38-I38 -> 0 | K38: 0 | L38: =H38-K38 -> 0 | M38: ELIGO | N38: CJ
H39: =SUM(C39:G39) -> 0 | J39: =H39-I39 -> 0 | K39: 0 | L39: =H39-K39 -> 0 | M39: ELIGO | N39: CJ
H40: =SUM(C40:G40) -> 0 | J40: =H40-I40 -> 0 | K40: 0 | L40: =H40-K40 -> 0 | M40: ELIGO | N40: CJ
...

Sheet Dashboard
A1: Rep # | B1: Rep Name | C1: COM Winbacks | H1: Residential | M1: Commercial | R1: DAILY TOTALS | W1: Grand Total
B2: FRONTERS | C2: Mon | D2: Tue | E2: Wed | F2: Thu | G2: Fri | H2: Mon | I2: Tue | J2: Wed | K2: Thu | L2: Fri | M2: Mon | N2: Tue | O2: Wed | P2: Thu | Q2: Fri | R2: Mon | S2: Tue | T2: Wed | U2: Thu | V2: Fri
A3: =Commercial!A3 -> 1291 | B3: =_xlfn.XLOOKUP(A3,Commercial!A:A,Commercial!B:B) -> Raven Mitchell (Commercial) | C3: =IFERROR(SUMIF('COM Winbacks'!$A:$A,$A3,'COM Winbacks'!C:C),0) -> 0 | D3: =IFERROR(SUMIF('COM Winbacks'!$A:$A,$A3,'COM Winbacks'!D:D),0) -> 0 | E3: =IFERROR(SUMIF('COM Winbacks'!$A:$A,$A3,'COM Winbacks'!E:E),0) -> 0 | F3: =IFERROR(SUMIF('COM Winbacks'!$A:$A,$A3,'COM Winbacks'!F:F),0) -> 0 | G3: =IFERROR(SUMIF('COM Winbacks'!$A:$A,$A3,'COM Winbacks'!G:G),0) -> 0 | H3: =IFERROR(SUMIF(Residential!$A:$A,$A3,Residential!C:C),0) -> 0 | I3: =IFERROR(SUMIF(Residential!$A:$A,$A3,Residential!D:D),0) -> 0 | J3: =IFERROR(SUMIF(Residential!$A:$A,$A3,Residential!E:E),0) -> 0 | K3: =IFERROR(SUMIF(Residential!$A:$A,$A3,Residential!F:F),0) -> 0 | L3: =IFERROR(SUMIF(Residential!$A:$A,$A3,Residential!G:G),0) -> 0 | M3: =IFERROR(SUMIF(Commercial!$A$3:$A$15,$A3,Commercial!C$3:C$15),0) -> 0 | N3: =IFERROR(SUMIF(Commercial!$A$3:$A$15,$A3,Commercial!D$3:D$15),0) -> 0 | O3: =IFERROR(SUMIF(Commercial!$A$3:$A$15,$A3,Commercial!E$3:E$15),0) -> 0 | P3: =IFERROR(SUMIF(Commercial!$A$3:$A$15,$A3,Commercial!F$3:F$15),0) -> 0 | Q3: =IFERROR(SUMIF(Commercial!$A$3:$A$15,$A3,Commercial!G$3:G$15),0) -> 0 | R3: =C3+H3+M3 -> 0 | S3: =D3+I3+N3 -> 0 | T3: =E3+J3+O3 -> 0 | U3: =F3+K3+P3 -> 0 | V3: =G3+L3+Q3 -> 0 | W3: =SUM(R3:V3) -> 0
A4: =Commercial!A4 -> 1292 | B4: =_xlfn.XLOOKUP(A4,Commercial!A:A,Commercial!B:B) -> Jakarta Hunter (Commercial) | C4: =IFERROR(SUMIF('COM Winbacks'!$A:$A,$A4,'COM Winbacks'!C:C),0) -> 0 | D4: =IFERROR(SUMIF('COM Winbacks'!$A:$A,$A4,'COM Winbacks'!D:D),0) -> 0 | E4: =IFERROR(SUMIF('COM Winbacks'!$A:$A,$A4,'COM Winbacks'!E:E),0) -> 0 | F4: =IFERROR(SUMIF('COM Winbacks'!$A:$A,$A4,'COM Winbacks'!F:F),0) -> 0 | G4: =IFERROR(SUMIF('COM Winbacks'!$A:$A,$A4,'COM Winbacks'!G:G),0) -> 0 | H4: =IFERROR(SUMIF(Residential!$A:$A,$A4,Residential!C:C),0) -> 0 | I4: =IFERROR(SUMIF(Residential!$A:$A,$A4,Residential!D:D),0) -> 0 | J4: =IFERROR(SUMIF(Residential!$A:$A,$A4,Residential!E:E),0) -> 0 | K4: =IFERROR(SUMIF(Residential!$A:$A,$A4,Residential!F:F),0) -> 0 | L4: =IFERROR(SUMIF(Residential!$A:$A,$A4,Residential!G:G),0) -> 0 | M4: =IFERROR(SUMIF(Commercial!$A$3:$A$15,$A4,Commercial!C$3:C$15),0) -> 1 | N4: =IFERROR(SUMIF(Commercial!$A$3:$A$15,$A4,Commercial!D$3:D$15),0) -> 0 | O4: =IFERROR(SUMIF(Commercial!$A$3:$A$15,$A4,Commercial!E$3:E$15),0) -> 0 | P4: =IFERROR(SUMIF(Commercial!$A$3:$A$15,$A4,Commercial!F$3:F$15),0) -> 0 | Q4: =IFERROR(SUMIF(Commercial!$A$3:$A$15,$A4,Commercial!G$3:G$15),0) -> 0 | R4: =C4+H4+M4 -> 1 | S4: =D4+I4+N4 -> 0 | T4: =E4+J4+O4 -> 0 | U4: =F4+K4+P4 -> 0 | V4: =G4+L4+Q4 -> 0 | W4: =SUM(R4:V4) -> 1
A5: =Commercial!A5 -> 1295 | B5: =_xlfn.XLOOKUP(A5,Commercial!A:A,Commercial!B:B) -> Luis Buitrago (Commercial) | C5: =IFERROR(SUMIF('COM Winbacks'!$A:$A,$A5,'COM Winbacks'!C:C),0) -> 0 | D5: =IFERROR(SUMIF('COM Winbacks'!$A:$A,$A5,'COM Winbacks'!D:D),0) -> 0 | E5: =IFERROR(SUMIF('COM Winbacks'!$A:$A,$A5,'COM Winbacks'!E:E),0) -> 0 | F5: =IFERROR(SUMIF('COM Winbacks'!$A:$A,$A5,'COM Winbacks'!F:F),0) -> 0 | G5: =IFERROR(SUMIF('COM Winbacks'!$A:$A,$A5,'COM Winbacks'!G:G),0) -> 0 | H5: =IFERROR(SUMIF(Residential!$A:$A,$A5,Residential!C:C),0) -> 0 | I5: =IFERROR(SUMIF(Residential!$A:$A,$A5,Residential!D:D),0) -> 0 | J5: =IFERROR(SUMIF(Residential!$A:$A,$A5,Residential!E:E),0) -> 0 | K5: =IFERROR(SUMIF(Residential!$A:$A,$A5,Residential!F:F),0) -> 0 | L5: =IFERROR(SUMIF(Residential!$A:$A,$A5,Residential!G:G),0) -> 0 | M5: =IFERROR(SUMIF(Commercial!$A$3:$A$15,$A5,Commercial!C$3:C$15),0) -> 0 | N5: =IFERROR(SUMIF(Commercial!$A$3:$A$15,$A5,Commercial!D$3:D$15),0) -> 0 | O5: =IFERROR(SUMIF(Commercial!$A$3:$A$15,$A5,Commercial!E$3:E$15),0) -> 0 | P5: =IFERROR(SUMIF(Commercial!$A$3:$A$15,$A5,Commercial!F$3:F$15),0) -> 0 | Q5: =IFERROR(SUMIF(Commercial!$A$3:$A$15,$A5,Commercial!G$3:G$15),0) -> 0 | R5: =C5+H5+M5 -> 0 | S5: =D5+I5+N5 -> 0 | T5: =E5+J5+O5 -> 0 | U5: =F5+K5+P5 -> 0 | V5: =G5+L5+Q5 -> 0 | W5: =SUM(R5:V5) -> 0
A6: =Commercial!A6 -> 1290 | B6: =_xlfn.XLOOKUP(A6,Commercial!A:A,Commercial!B:B) -> Abigail Gambino (Commercial-Closer) | C6: =IFERROR(SUMIF('COM Winbacks'!$A:$A,$A6,'COM Winbacks'!C:C),0) -> 0 | D6: =IFERROR(SUMIF('COM Winbacks'!$A:$A,$A6,'COM Winbacks'!D:D),0) -> 0 | E6: =IFERROR(SUMIF('COM Winbacks'!$A:$A,$A6,'COM Winbacks'!E:E),0) -> 0 | F6: =IFERROR(SUMIF('COM Winbacks'!$A:$A,$A6,'COM Winbacks'!F:F),0) -> 0 | G6: =IFERROR(SUMIF('COM Winbacks'!$A:$A,$A6,'COM Winbacks'!G:G),0) -> 0 | H6: =IFERROR(SUMIF(Residential!$A:$A,$A6,Residential!C:C),0) -> 0 | I6: =IFERROR(SUMIF(Residential!$A:$A,$A6,Residential!D:D),0) -> 0 | J6: =IFERROR(SUMIF(Residential!$A:$A,$A6,Residential!E:E),0) -> 0 | K6: =IFERROR(SUMIF(Residential!$A:$A,$A6,Residential!F:F),0) -> 0 | L6: =IFERROR(SUMIF(Residential!$A:$A,$A6,Residential!G:G),0) -> 0 | M6: =IFERROR(SUMIF(Commercial!$A$3:$A$15,$A6,Commercial!C$3:C$15),0) -> 0 | N6: =IFERROR(SUMIF(Commercial!$A$3:$A$15,$A6,Commercial!D$3:D$15),0) -> 0 | O6: =IFERROR(SUMIF(Commercial!$A$3:$A$15,$A6,Commercial!E$3:E$15),0) -> 0 | P6: =IFERROR(SUMIF(Commercial!$A$3:$A$15,$A6,Commercial!F$3:F$15),0) -> 0 | Q6: =IFERROR(SUMIF(Commercial!$A$3:$A$15,$A6,Commercial!G$3:G$15),0) -> 0 | R6: =C6+H6+M6 -> 0 | S6: =D6+I6+N6 -> 0 | T6: =E6+J6+O6 -> 0 | U6: =F6+K6+P6 -> 0 | V6: =G6+L6+Q6 -> 0 | W6: =SUM(R6:V6) -> 0
A7: =Commercial!A7 -> 1288 | B7: =_xlfn.XLOOKUP(A7,Commercial!A:A,Commercial!B:B) -> Allen Alberts(Commercial-Closer) | C7: =IFERROR(SUMIF('COM Winbacks'!$A:$A,$A7,'COM Winbacks'!C:C),0) -> 0 | D7: =IFERROR(SUMIF('COM Winbacks'!$A:$A,$A7,'COM Winbacks'!D:D),0) -> 0 | E7: =IFERROR(SUMIF('COM Winbacks'!$A:$A,$A7,'COM Winbacks'!E:E),0) -> 0 | F7: =IFERROR(SUMIF('COM Winbacks'!$A:$A,$A7,'COM Winbacks'!F:F),0) -> 0 | G7: =IFERROR(SUMIF('COM Winbacks'!$A:$A,$A7,'COM Winbacks'!G:G),0) -> 0 | H7: =IFERROR(SUMIF(Residential!$A:$A,$A7,Residential!C:C),0) -> 0 | I7: =IFERROR(SUMIF(Residential!$A:$A,$A7,Residential!D:D),0) -> 0 | J7: =IFERROR(SUMIF(Residential!$A:$A,$A7,Residential!E:E),0) -> 0 | K7: =IFERROR(SUMIF(Residential!$A:$A,$A7,Residential!F:F),0) -> 0 | L7: =IFERROR(SUMIF(Residential!$A:$A,$A7,Residential!G:G),0) -> 0 | M7: =IFERROR(SUMIF(Commercial!$A$3:$A$15,$A7,Commercial!C$3:C$15),0) -> 0 | N7: =IFERROR(SUMIF(Commercial!$A$3:$A$15,$A7,Commercial!D$3:D$15),0) -> 0 | O7: =IFERROR(SUMIF(Commercial!$A$3:$A$15,$A7,Commercial!E$3:E$15),0) -> 0 | P7: =IFERROR(SUMIF(Commercial!$A$3:$A$15,$A7,Commercial!F$3:F$15),0) -> 0 | Q7: =IFERROR(SUMIF(Commercial!$A$3:$A$15,$A7,Commercial!G$3:G$15),0) -> 0 | R7: =C7+H7+M7 -> 0 | S7: =D7+I7+N7 -> 0 | T7: =E7+J7+O7 -> 0 | U7: =F7+K7+P7 -> 0 | V7: =G7+L7+Q7 -> 0 | W7: =SUM(R7:V7) -> 0
A8: =Commercial!A8 -> 1175 | B8: =_xlfn.XLOOKUP(A8,Commercial!A:A,Commercial!B:B) -> Kenticka Tate (Remote)(Commercial) | C8: =IFERROR(SUMIF('COM Winbacks'!$A:$A,$A8,'COM Winbacks'!C:C),0) -> 0 | D8: =IFERROR(SUMIF('COM Winbacks'!$A:$A,$A8,'COM Winbacks'!D:D),0) -> 0 | E8: =IFERROR(SUMIF('COM Winbacks'!$A:$A,$A8,'COM Winbacks'!E:E),0) -> 0 | F8: =IFERROR(SUMIF('COM Winbacks'!$A:$A,$A8,'COM Winbacks'!F:F),0) -> 0 | G8: =IFERROR(SUMIF('COM Winbacks'!$A:$A,$A8,'COM Winbacks'!G:G),0) -> 0 | H8: =IFERROR(SUMIF(Residential!$A:$A,$A8,Residential!C:C),0) -> 0 | I8: =IFERROR(SUMIF(Residential!$A:$A,$A8,Residential!D:D),0) -> 0 | J8: =IFERROR(SUMIF(Residential!$A:$A,$A8,Residential!E:E),0) -> 0 | K8: =IFERROR(SUMIF(Residential!$A:$A,$A8,Residential!F:F),0) -> 0 | L8: =IFERROR(SUMIF(Residential!$A:$A,$A8,Residential!G:G),0) -> 0 | M8: =IFERROR(SUMIF(Commercial!$A$3:$A$15,$A8,Commercial!C$3:C$15),0) -> 2 | N8: =IFERROR(SUMIF(Commercial!$A$3:$A$15,$A8,Commercial!D$3:D$15),0) -> 0 | O8: =IFERROR(SUMIF(Commercial!$A$3:$A$15,$A8,Commercial!E$3:E$15),0) -> 0 | P8: =IFERROR(SUMIF(Commercial!$A$3:$A$15,$A8,Commercial!F$3:F$15),0) -> 0 | Q8: =IFERROR(SUMIF(Commercial!$A$3:$A$15,$A8,Commercial!G$3:G$15),0) -> 0 | R8: =C8+H8+M8 -> 2 | S8: =D8+I8+N8 -> 0 | T8: =E8+J8+O8 -> 0 | U8: =F8+K8+P8 -> 0 | V8: =G8+L8+Q8 -> 0 | W8: =SUM(R8:V8) -> 2
A9: =Commercial!A9 -> 1294 | B9: =_xlfn.XLOOKUP(A9,Commercial!A:A,Commercial!B:B) -> Brandy Paton (Commercial) | C9: =IFERROR(SUMIF('COM Winbacks'!$A:$A,$A9,'COM Winbacks'!C:C),0) -> 0 | D9: =IFERROR(SUMIF('COM Winbacks'!$A:$A,$A9,'COM Winbacks'!D:D),0) -> 0 | E9: =IFERROR(SUMIF('COM Winbacks'!$A:$A,$A9,'COM Winbacks'!E:E),0) -> 0 | F9: =IFERROR(SUMIF('COM Winbacks'!$A:$A,$A9,'COM Winbacks'!F:F),0) -> 0 | G9: =IFERROR(SUMIF('COM Winbacks'!$A:$A,$A9,'COM Winbacks'!G:G),0) -> 0 | H9: =IFERROR(SUMIF(Residential!$A:$A,$A9,Residential!C:C),0) -> 0 | I9: =IFERROR(SUMIF(Residential!$A:$A,$A9,Residential!D:D),0) -> 0 | J9: =IFERROR(SUMIF(Residential!$A:$A,$A9,Residential!E:E),0) -> 0 | K9: =IFERROR(SUMIF(Residential!$A:$A,$A9,Residential!F:F),0) -> 0 | L9: =IFERROR(SUMIF(Residential!$A:$A,$A9,Residential!G:G),0) -> 0 | M9: =IFERROR(SUMIF(Commercial!$A$3:$A$15,$A9,Commercial!C$3:C$15),0) -> 0 | N9: =IFERROR(SUMIF(Commercial!$A$3:$A$15,$A9,Commercial!D$3:D$15),0) -> 0 | O9: =IFERROR(SUMIF(Commercial!$A$3:$A$15,$A9,Commercial!E$3:E$15),0) -> 0 | P9: =IFERROR(SUMIF(Commercial!$A$3:$A$15,$A9,Commercial!F$3:F$15),0) -> 0 | Q9: =IFERROR(SUMIF(Commercial!$A$3:$A$15,$A9,Commercial!G$3:G$15),0) -> 0 | R9: =C9+H9+M9 -> 0 | S9: =D9+I9+N9 -> 0 | T9: =E9+J9+O9 -> 0 | U9: =F9+K9+P9 -> 0 | V9: =G9+L9+Q9 -> 0 | W9: =SUM(R9:V9) -> 0
A10: =Commercial!A10 -> 1280 | B10: =_xlfn.XLOOKUP(A10,Commercial!A:A,Commercial!B:B) -> Ashlee Franks (Commercial) | C10: =IFERROR(SUMIF('COM Winbacks'!$A:$A,$A10,'COM Winbacks'!C:C),0) -> 0 | D10: =IFERROR(SUMIF('COM Winbacks'!$A:$A,$A10,'COM Winbacks'!D:D),0) -> 0 | E10: =IFERROR(SUMIF('COM Winbacks'!$A:$A,$A10,'COM Winbacks'!E:E),0) -> 0 | F10: =IFERROR(SUMIF('COM Winbacks'!$A:$A,$A10,'COM Winbacks'!F:F),0) -> 0 | G10: =IFERROR(SUMIF('COM Winbacks'!$A:$A,$A10,'COM Winbacks'!G:G),0) -> 0 | H10: =IFERROR(SUMIF(Residential!$A:$A,$A10,Residential!C:C),0) -> 0 | I10: =IFERROR(SUMIF(Residential!$A:$A,$A10,Residential!D:D),0) -> 0 | J10: =IFERROR(SUMIF(Residential!$A:$A,$A10,Residential!E:E),0) -> 0 | K10: =IFERROR(SUMIF(Residential!$A:$A,$A10,Residential!F:F),0) -> 0 | L10: =IFERROR(SUMIF(Residential!$A:$A,$A10,Residential!G:G),0) -> 0 | M10: =IFERROR(SUMIF(Commercial!$A$3:$A$15,$A10,Commercial!C$3:C$15),0) -> 0 | N10: =IFERROR(SUMIF(Commercial!$A$3:$A$15,$A10,Commercial!D$3:D$15),0) -> 0 | O10: =IFERROR(SUMIF(Commercial!$A$3:$A$15,$A10,Commercial!E$3:E$15),0) -> 0 | P10: =IFERROR(SUMIF(Commercial!$A$3:$A$15,$A10,Commercial!F$3:F$15),0) -> 0 | Q10: =IFERROR(SUMIF(Commercial!$A$3:$A$15,$A10,Commercial!G$3:G$15),0) -> 0 | R10: =C10+H10+M10 -> 0 | S10: =D10+I10+N10 -> 0 | T10: =E10+J10+O10 -> 0 | U10: =F10+K10+P10 -> 0 | V10: =G10+L10+Q10 -> 0 | W10: =SUM(R10:V10) -> 0
A11: =Commercial!A11 -> 1298 | B11: =_xlfn.XLOOKUP(A11,Commercial!A:A,Commercial!B:B) -> Shelby Lewis (Commercial) | C11: =IFERROR(SUMIF('COM Winbacks'!$A:$A,$A11,'COM Winbacks'!C:C),0) -> 0 | D11: =IFERROR(SUMIF('COM Winbacks'!$A:$A,$A11,'COM Winbacks'!D:D),0) -> 0 | E11: =IFERROR(SUMIF('COM Winbacks'!$A:$A,$A11,'COM Winbacks'!E:E),0) -> 0 | F11: =IFERROR(SUMIF('COM Winbacks'!$A:$A,$A11,'COM Winbacks'!F:F),0) -> 0 | G11: =IFERROR(SUMIF('COM Winbacks'!$A:$A,$A11,'COM Winbacks'!G:G),0) -> 0 | H11: =IFERROR(SUMIF(Residential!$A:$A,$A11,Residential!C:C),0) -> 0 | I11: =IFERROR(SUMIF(Residential!$A:$A,$A11,Residential!D:D),0) -> 0 | J11: =IFERROR(SUMIF(Residential!$A:$A,$A11,Residential!E:E),0) -> 0 | K11: =IFERROR(SUMIF(Residential!$A:$A,$A11,Residential!F:F),0) -> 0 | L11: =IFERROR(SUMIF(Residential!$A:$A,$A11,Residential!G:G),0) -> 0 | M11: =IFERROR(SUMIF(Commercial!$A$3:$A$15,$A11,Commercial!C$3:C$15),0) -> 0 | N11: =IFERROR(SUMIF(Commercial!$A$3:$A$15,$A11,Commercial!D$3:D$15),0) -> 0 | O11: =IFERROR(SUMIF(Commercial!$A$3:$A$15,$A11,Commercial!E$3:E$15),0) -> 0 | P11: =IFERROR(SUMIF(Commercial!$A$3:$A$15,$A11,Commercial!F$3:F$15),0) -> 0 | Q11: =IFERROR(SUMIF(Commercial!$A$3:$A$15,$A11,Commercial!G$3:G$15),0) -> 0 | R11: =C11+H11+M11 -> 0 | S11: =D11+I11+N11 -> 0 | T11: =E11+J11+O11 -> 0 | U11: =F11+K11+P11 -> 0 | V11: =G11+L11+Q11 -> 0 | W11: =SUM(R11:V11) -> 0
A12: =Commercial!A12 -> 1300 | B12: =_xlfn.XLOOKUP(A12,Commercial!A:A,Commercial!B:B) -> Neil Singhal (Commercial) | C12: =IFERROR(SUMIF('COM Winbacks'!$A:$A,$A12,'COM Winbacks'!C:C),0) -> 0 | D12: =IFERROR(SUMIF('COM Winbacks'!$A:$A,$A12,'COM Winbacks'!D:D),0) -> 0 | E12: =IFERROR(SUMIF('COM Winbacks'!$A:$A,$A12,'COM Winbacks'!E:E),0) -> 0 | F12: =IFERROR(SUMIF('COM Winbacks'!$A:$A,$A12,'COM Winbacks'!F:F),0) -> 0 | G12: =IFERROR(SUMIF('COM Winbacks'!$A:$A,$A12,'COM Winbacks'!G:G),0) -> 0 | H12: =IFERROR(SUMIF(Residential!$A:$A,$A12,Residential!C:C),0) -> 0 | I12: =IFERROR(SUMIF(Residential!$A:$A,$A12,Residential!D:D),0) -> 0 | J12: =IFERROR(SUMIF(Residential!$A:$A,$A12,Residential!E:E),0) -> 0 | K12: =IFERROR(SUMIF(Residential!$A:$A,$A12,Residential!F:F),0) -> 0 | L12: =IFERROR(SUMIF(Residential!$A:$A,$A12,Residential!G:G),0) -> 0 | M12: =IFERROR(SUMIF(Commercial!$A$3:$A$15,$A12,Commercial!C$3:C$15),0) -> 0 | N12: =IFERROR(SUMIF(Commercial!$A$3:$A$15,$A12,Commercial!D$3:D$15),0) -> 0 | O12: =IFERROR(SUMIF(Commercial!$A$3:$A$15,$A12,Commercial!E$3:E$15),0) -> 0 | P12: =IFERROR(SUMIF(Commercial!$A$3:$A$15,$A12,Commercial!F$3:F$15),0) -> 0 | Q12: =IFERROR(SUMIF(Commercial!$A$3:$A$15,$A12,Commercial!G$3:G$15),0) -> 0 | R12: =C12+H12+M12 -> 0 | S12: =D12+I12+N12 -> 0 | T12: =E12+J12+O12 -> 0 | U12: =F12+K12+P12 -> 0 | V12: =G12+L12+Q12 -> 0 | W12: =SUM(R12:V12) -> 0
A13: =Commercial!A13 -> 1301 | B13: =_xlfn.XLOOKUP(A13,Commercial!A:A,Commercial!B:B) -> Albert Williams (Commercial) | C13: =IFERROR(SUMIF('COM Winbacks'!$A:$A,$A13,'COM Winbacks'!C:C),0) -> 0 | D13: =IFERROR(SUMIF('COM Winbacks'!$A:$A,$A13,'COM Winbacks'!D:D),0) -> 0 | E13: =IFERROR(SUMIF('COM Winbacks'!$A:$A,$A13,'COM Winbacks'!E:E),0) -> 0 | F13: =IFERROR(SUMIF('COM Winbacks'!$A:$A,$A13,'COM Winbacks'!F:F),0) -> 0 | G13: =IFERROR(SUMIF('COM Winbacks'!$A:$A,$A13,'COM Winbacks'!G:G),0) -> 0 | H13: =IFERROR(SUMIF(Residential!$A:$A,$A13,Residential!C:C),0) -> 0 | I13: =IFERROR(SUMIF(Residential!$A:$A,$A13,Residential!D:D),0) -> 0 | J13: =IFERROR(SUMIF(Residential!$A:$A,$A13,Residential!E:E),0) -> 0 | K13: =IFERROR(SUMIF(Residential!$A:$A,$A13,Residential!F:F),0) -> 0 | L13: =IFERROR(SUMIF(Residential!$A:$A,$A13,Residential!G:G),0) -> 0 | M13: =IFERROR(SUMIF(Commercial!$A$3:$A$15,$A13,Commercial!C$3:C$15),0) -> 0 | N13: =IFERROR(SUMIF(Commercial!$A$3:$A$15,$A13,Commercial!D$3:D$15),0) -> 0 | O13: =IFERROR(SUMIF(Commercial!$A$3:$A$15,$A13,Commercial!E$3:E$15),0) -> 0 | P13: =IFERROR(SUMIF(Commercial!$A$3:$A$15,$A13,Commercial!F$3:F$15),0) -> 0 | Q13: =IFERROR(SUMIF(Commercial!$A$3:$A$15,$A13,Commercial!G$3:G$15),0) -> 0 | R13: =C13+H13+M13 -> 0 | S13: =D13+I13+N13 -> 0 | T13: =E13+J13+O13 -> 0 | U13: =F13+K13+P13 -> 0 | V13: =G13+L13+Q13 -> 0 | W13: =SUM(R13:V13) -> 0
B15: CLOSERS | W15: =SUM(W3:W14) -> 3
A16: =Commercial!A19 -> 1290 | B16: =_xlfn.XLOOKUP(A16,Commercial!A:A,Commercial!B:B) -> Abigail Gambino (Commercial-Closer) | C16: =IFERROR(SUMIF('COM Winbacks'!$A:$A,$A16,'COM Winbacks'!C:C),0) -> 0 | D16: =IFERROR(SUMIF('COM Winbacks'!$A:$A,$A16,'COM Winbacks'!D:D),0) -> 0 | E16: =IFERROR(SUMIF('COM Winbacks'!$A:$A,$A16,'COM Winbacks'!E:E),0) -> 0 | F16: =IFERROR(SUMIF('COM Winbacks'!$A:$A,$A16,'COM Winbacks'!F:F),0) -> 0 | G16: =IFERROR(SUMIF('COM Winbacks'!$A:$A,$A16,'COM Winbacks'!G:G),0) -> 0 | H16: =IFERROR(SUMIF(Residential!$A:$A,$A16,Residential!C:C),0) -> 0 | I16: =IFERROR(SUMIF(Residential!$A:$A,$A16,Residential!D:D),0) -> 0 | J16: =IFERROR(SUMIF(Residential!$A:$A,$A16,Residential!E:E),0) -> 0 | K16: =IFERROR(SUMIF(Residential!$A:$A,$A16,Residential!F:F),0) -> 0 | L16: =IFERROR(SUMIF(Residential!$A:$A,$A16,Residential!G:G),0) -> 0 | M16: =IFERROR(SUMIF(Commercial!$A$19:$A$24,$A16,Commercial!C$19:C$24),0) -> 0 | N16: =IFERROR(SUMIF(Commercial!$A$19:$A$24,$A16,Commercial!D$19:D$24),0) -> 0 | O16: =IFERROR(SUMIF(Commercial!$A$19:$A$24,$A16,Commercial!E$19:E$24),0) -> 0 | P16: =IFERROR(SUMIF(Commercial!$A$19:$A$24,$A16,Commercial!F$19:F$24),0) -> 0 | Q16: =IFERROR(SUMIF(Commercial!$A$19:$A$24,$A16,Commercial!G$19:G$24),0) -> 0 | R16: =C16+H16+M16 -> 0 | S16: =D16+I16+N16 -> 0 | T16: =E16+J16+O16 -> 0 | U16: =F16+K16+P16 -> 0 | V16: =G16+L16+Q16 -> 0 | W16: =SUM(R16:V16) -> 0
A17: =Commercial!A20 -> 1288 | B17: =_xlfn.XLOOKUP(A17,Commercial!A:A,Commercial!B:B) -> Allen Alberts(Commercial-Closer) | C17: =IFERROR(SUMIF('COM Winbacks'!$A:$A,$A17,'COM Winbacks'!C:C),0) -> 0 | D17: =IFERROR(SUMIF('COM Winbacks'!$A:$A,$A17,'COM Winbacks'!D:D),0) -> 0 | E17: =IFERROR(SUMIF('COM Winbacks'!$A:$A,$A17,'COM Winbacks'!E:E),0) -> 0 | F17: =IFERROR(SUMIF('COM Winbacks'!$A:$A,$A17,'COM Winbacks'!F:F),0) -> 0 | G17: =IFERROR(SUMIF('COM Winbacks'!$A:$A,$A17,'COM Winbacks'!G:G),0) -> 0 | H17: =IFERROR(SUMIF(Residential!$A:$A,$A17,Residential!C:C),0) -> 0 | I17: =IFERROR(SUMIF(Residential!$A:$A,$A17,Residential!D:D),0) -> 0 | J17: =IFERROR(SUMIF(Residential!$A:$A,$A17,Residential!E:E),0) -> 0 | K17: =IFERROR(SUMIF(Residential!$A:$A,$A17,Residential!F:F),0) -> 0 | L17: =IFERROR(SUMIF(Residential!$A:$A,$A17,Residential!G:G),0) -> 0 | M17: =IFERROR(SUMIF(Commercial!$A$19:$A$24,$A17,Commercial!C$19:C$24),0) -> 0 | N17: =IFERROR(SUMIF(Commercial!$A$19:$A$24,$A17,Commercial!D$19:D$24),0) -> 0 | O17: =IFERROR(SUMIF(Commercial!$A$19:$A$24,$A17,Commercial!E$19:E$24),0) -> 0 | P17: =IFERROR(SUMIF(Commercial!$A$19:$A$24,$A17,Commercial!F$19:F$24),0) -> 0 | Q17: =IFERROR(SUMIF(Commercial!$A$19:$A$24,$A17,Commercial!G$19:G$24),0) -> 0 | R17: =C17+H17+M17 -> 0 | S17: =D17+I17+N17 -> 0 | T17: =E17+J17+O17 -> 0 | U17: =F17+K17+P17 -> 0 | V17: =G17+L17+Q17 -> 0 | W17: =SUM(R17:V17) -> 0
A18: =Commercial!A21 -> 1151 | B18: =_xlfn.XLOOKUP(A18,Commercial!A:A,Commercial!B:B) -> CJ Jackson (Manager/Closer) | C18: =IFERROR(SUMIF('COM Winbacks'!$A:$A,$A18,'COM Winbacks'!C:C),0) -> 0 | D18: =IFERROR(SUMIF('COM Winbacks'!$A:$A,$A18,'COM Winbacks'!D:D),0) -> 0 | E18: =IFERROR(SUMIF('COM Winbacks'!$A:$A,$A18,'COM Winbacks'!E:E),0) -> 0 | F18: =IFERROR(SUMIF('COM Winbacks'!$A:$A,$A18,'COM Winbacks'!F:F),0) -> 0 | G18: =IFERROR(SUMIF('COM Winbacks'!$A:$A,$A18,'COM Winbacks'!G:G),0) -> 0 | H18: =IFERROR(SUMIF(Residential!$A:$A,$A18,Residential!C:C),0) -> 0 | I18: =IFERROR(SUMIF(Residential!$A:$A,$A18,Residential!D:D),0) -> 0 | J18: =IFERROR(SUMIF(Residential!$A:$A,$A18,Residential!E:E),0) -> 0 | K18: =IFERROR(SUMIF(Residential!$A:$A,$A18,Residential!F:F),0) -> 0 | L18: =IFERROR(SUMIF(Residential!$A:$A,$A18,Residential!G:G),0) -> 0 | M18: =IFERROR(SUMIF(Commercial!$A$19:$A$24,$A18,Commercial!C$19:C$24),0) -> 0 | N18: =IFERROR(SUMIF(Commercial!$A$19:$A$24,$A18,Commercial!D$19:D$24),0) -> 0 | O18: =IFERROR(SUMIF(Commercial!$A$19:$A$24,$A18,Commercial!E$19:E$24),0) -> 0 | P18: =IFERROR(SUMIF(Commercial!$A$19:$A$24,$A18,Commercial!F$19:F$24),0) -> 0 | Q18: =IFERROR(SUMIF(Commercial!$A$19:$A$24,$A18,Commercial!G$19:G$24),0) -> 0 | R18: =C18+H18+M18 -> 0 | S18: =D18+I18+N18 -> 0 | T18: =E18+J18+O18 -> 0 | U18: =F18+K18+P18 -> 0 | V18: =G18+L18+Q18 -> 0 | W18: =SUM(R18:V18) -> 0
A19: =Commercial!A22 -> 1294 | B19: =_xlfn.XLOOKUP(A19,Commercial!A:A,Commercial!B:B) -> Brandy Paton (Commercial) | C19: =IFERROR(SUMIF('COM Winbacks'!$A:$A,$A19,'COM Winbacks'!C:C),0) -> 0 | D19: =IFERROR(SUMIF('COM Winbacks'!$A:$A,$A19,'COM Winbacks'!D:D),0) -> 0 | E19: =IFERROR(SUMIF('COM Winbacks'!$A:$A,$A19,'COM Winbacks'!E:E),0) -> 0 | F19: =IFERROR(SUMIF('COM Winbacks'!$A:$A,$A19,'COM Winbacks'!F:F),0) -> 0 | G19: =IFERROR(SUMIF('COM Winbacks'!$A:$A,$A19,'COM Winbacks'!G:G),0) -> 0 | H19: =IFERROR(SUMIF(Residential!$A:$A,$A19,Residential!C:C),0) -> 0 | I19: =IFERROR(SUMIF(Residential!$A:$A,$A19,Residential!D:D),0) -> 0 | J19: =IFERROR(SUMIF(Residential!$A:$A,$A19,Residential!E:E),0) -> 0 | K19: =IFERROR(SUMIF(Residential!$A:$A,$A19,Residential!F:F),0) -> 0 | L19: =IFERROR(SUMIF(Residential!$A:$A,$A19,Residential!G:G),0) -> 0 | M19: =IFERROR(SUMIF(Commercial!$A$19:$A$24,$A19,Commercial!C$19:C$24),0) -> 0 | N19: =IFERROR(SUMIF(Commercial!$A$19:$A$24,$A19,Commercial!D$19:D$24),0) -> 0 | O19: =IFERROR(SUMIF(Commercial!$A$19:$A$24,$A19,Commercial!E$19:E$24),0) -> 0 | P19: =IFERROR(SUMIF(Commercial!$A$19:$A$24,$A19,Commercial!F$19:F$24),0) -> 0 | Q19: =IFERROR(SUMIF(Commercial!$A$19:$A$24,$A19,Commercial!G$19:G$24),0) -> 0 | R19: =C19+H19+M19 -> 0 | S19: =D19+I19+N19 -> 0 | T19: =E19+J19+O19 -> 0 | U19: =F19+K19+P19 -> 0 | V19: =G19+L19+Q19 -> 0 | W19: =SUM(R19:V19) -> 0
A20: =Commercial!A23 -> 1300 | B20: =_xlfn.XLOOKUP(A20,Commercial!A:A,Commercial!B:B) -> Neil Singhal (Commercial) | C20: =IFERROR(SUMIF('COM Winbacks'!$A:$A,$A20,'COM Winbacks'!C:C),0) -> 0 | D20: =IFERROR(SUMIF('COM Winbacks'!$A:$A,$A20,'COM Winbacks'!D:D),0) -> 0 | E20: =IFERROR(SUMIF('COM Winbacks'!$A:$A,$A20,'COM Winbacks'!E:E),0) -> 0 | F20: =IFERROR(SUMIF('COM Winbacks'!$A:$A,$A20,'COM Winbacks'!F:F),0) -> 0 | G20: =IFERROR(SUMIF('COM Winbacks'!$A:$A,$A20,'COM Winbacks'!G:G),0) -> 0 | H20: =IFERROR(SUMIF(Residential!$A:$A,$A20,Residential!C:C),0) -> 0 | I20: =IFERROR(SUMIF(Residential!$A:$A,$A20,Residential!D:D),0) -> 0 | J20: =IFERROR(SUMIF(Residential!$A:$A,$A20,Residential!E:E),0) -> 0 | K20: =IFERROR(SUMIF(Residential!$A:$A,$A20,Residential!F:F),0) -> 0 | L20: =IFERROR(SUMIF(Residential!$A:$A,$A20,Residential!G:G),0) -> 0 | M20: =IFERROR(SUMIF(Commercial!$A$19:$A$24,$A20,Commercial!C$19:C$24),0) -> 2 | N20: =IFERROR(SUMIF(Commercial!$A$19:$A$24,$A20,Commercial!D$19:D$24),0) -> 0 | O20: =IFERROR(SUMIF(Commercial!$A$19:$A$24,$A20,Commercial!E$19:E$24),0) -> 0 | P20: =IFERROR(SUMIF(Commercial!$A$19:$A$24,$A20,Commercial!F$19:F$24),0) -> 0 | Q20: =IFERROR(SUMIF(Commercial!$A$19:$A$24,$A20,Commercial!G$19:G$24),0) -> 0 | R20: =C20+H20+M20 -> 2 | S20: =D20+I20+N20 -> 0 | T20: =E20+J20+O20 -> 0 | U20: =F20+K20+P20 -> 0 | V20: =G20+L20+Q20 -> 0 | W20: =SUM(R20:V20) -> 2
B21: TOTAL | C21: =SUM(C3:C20) -> 0 | D21: =SUM(D3:D20) -> 0 | E21: =SUM(E3:E20) -> 0 | F21: =SUM(F3:F20) -> 0 | G21: =SUM(G3:G20) -> 0 | H21: =SUM(H3:H20) -> 0 | I21: =SUM(I3:I20) -> 0 | J21: =SUM(J3:J20) -> 0 | ... V21: =SUM(V3:V20) -> 0 | W21: =SUM(W16:W20) -> 2
