Workbook

Sheet Commercial
A1: Rep # | B1: Rep Name | C1: Monday | J1: Tuesday | P1: Wednesday | V1: Thursday | AB1: Friday | AG1: Total COMP | AH1: BAD TPV | AI1: TOTAL RESI | AJ1: TOTAL WK | AK1: Last Week | AL1: Difference | AM1: Total Hrs | AN1: SPH | AO1: MWH Total | AP1: Program | AQ1: Manager
B2: Commercial Agents | C2: Hrs | D2: Front | E2: Sales | F2: Resi | G2: SPH | H2: MGW | I2: Hrs | J2: Front | K2: Sales | L2: Resi | M2: SPH | N2: MGW | O2: Hrs | P2: Front | Q2: Sales | R2: Resi | S2: SPH | T2: MGW | U2: Hrs | V2: Front | W2: Sales | X2: Resi | Y2: SPH | Z2: MGW | AA2: Hrs | AB2: Front | AC2: Sales | AD2: Resi | AE2: SPH | AF2: MGW
A3: 1291 | B3: Raven Mitchell (Commercial) | C3: {=_xlfn.XLOOKUP(A3,'Agents Hrs'!A:A,'Agents Hrs'!D:D,0,0)} -> 7 | G3: =IFERROR(E3/C3, 0) -> 0 | I3: {=_xlfn.XLOOKUP(A3,'Agents Hrs'!A:A,'Agents Hrs'!F:F,0,0)} -> 7.5 | K3: 1 | M3: =IFERROR(K3/I3, 0) -> 0.13333333 | O3: {=_xlfn.XLOOKUP(A3,'Agents Hrs'!A:A,'Agents Hrs'!H:H,0,0)} -> 6.75 | P3: 3 | Q3: 3 | S3: =IFERROR(Q3/O3, 0) -> 0.44444444 | U3: {=_xlfn.XLOOKUP(A3,'Agents Hrs'!A:A,'Agents Hrs'!J:J,0,0)} -> 6.75 | V3: 2 | W3: 0 | Y3: =IFERROR(W3/U3, 0) -> 0 | AA3: {=_xlfn.XLOOKUP(A3,'Agents Hrs'!A:A,'Agents Hrs'!L:L,0,0)} -> 7.5 | AB3: 1 | AC3: 0 | AE3: =IFERROR(AC3/AA3, 0) -> 0 | AG3: =SUM(E3,K3,Q3,W3,AC3) -> 4 | AI3: =SUM(F3,L3,R3,X3,AD3) -> 0 | AJ3: =AG3-AH3 -> 4 | AK3: 4 | AL3: =AG3-AK3 -> 0 | AM3: =SUM(C3,I3,O3,U3,AA3) -> 35.5 | AN3: =IFERROR(AG3/AM3, 0) -> 0.11267606 | AO3: =SUM(H3,N3,T3,Z3,AF3) -> 0 | AP3: ELIGO | AQ3: CJ
A4: 1292 | B4: Jakarta Hunter (Commercial) | C4: {=_xlfn.XLOOKUP(A4,'Agents Hrs'!A:A,'Agents Hrs'!D:D,0,0)} -> 7 | E4: 1 | G4: =IFERROR(E4/C4, 0) -> 0.14285714 | I4: {=_xlfn.XLOOKUP(A4,'Agents Hrs'!A:A,'Agents Hrs'!F:F,0,0)} -> 7 | M4: =IFERROR(K4/I4, 0) -> 0 | O4: {=_xlfn.XLOOKUP(A4,'Agents Hrs'!A:A,'Agents Hrs'!H:H,0,0)} -> 8 | P4: 0 | Q4: 0 | S4: =IFERROR(Q4/O4, 0) -> 0 | U4: {=_xlfn.XLOOKUP(A4,'Agents Hrs'!A:A,'Agents Hrs'!J:J,0,0)} -> 7.75 | W4: 0 | Y4: =IFERROR(W4/U4, 0) -> 0 | AA4: {=_xlfn.XLOOKUP(A4,'Agents Hrs'!A:A,'Agents Hrs'!L:L,0,0)} -> 3.15 | AB4: 0 | AC4: 0 | AE4: =IFERROR(AC4/AA4, 0) -> 0 | AG4: =SUM(E4,K4,Q4,W4,AC4) -> 1 | AI4: =SUM(F4,L4,R4,X4,AD4) -> 0 | AJ4: =AG4-AH4 -> 1 | AK4: 1 | AL4: =AG4-AK4 -> 0 | AM4: =SUM(C4,I4,O4,U4,AA4) -> 32.9 | AN4: =IFERROR(AG4/AM4, 0) -> 0.030395137 | AO4: =SUM(H4,N4,T4,Z4,AF4) -> 0 | AP4: ELIGO | AQ4: CJ
A5: 1295 | B5: Luis Buitrago (Commercial) | C5: {=_xlfn.XLOOKUP(A5,'Agents Hrs'!A:A,'Agents Hrs'!D:D,0,0)} -> 7 | G5: =IFERROR(E5/C5, 0) -> 0 | I5: {=_xlfn.XLOOKUP(A5,'Agents Hrs'!A:A,'Agents Hrs'!F:F,0,0)} -> 7 | M5: =IFERROR(K5/I5, 0) -> 0 | O5: {=_xlfn.XLOOKUP(A5,'Agents Hrs'!A:A,'Agents Hrs'!H:H,0,0)} -> 7 | P5: 0 | Q5: 0 | S5: =IFERROR(Q5/O5, 0) -> 0 | U5: {=_xlfn.XLOOKUP(A5,'Agents Hrs'!A:A,'Agents Hrs'!J:J,0,0)} -> 6.75 | W5: 0 | Y5: =IFERROR(W5/U5, 0) -> 0 | AA5: {=_xlfn.XLOOKUP(A5,'Agents Hrs'!A:A,'Agents Hrs'!L:L,0,0)} -> 7.75 | AB5: 0 | AC5: 0 | AE5: =IFERROR(AC5/AA5, 0) -> 0 | AG5: =SUM(E5,K5,Q5,W5,AC5) -> 0 | AI5: =SUM(F5,L5,R5,X5,AD5) -> 0 | AJ5: =AG5-AH5 -> 0 | AK5: 1 | AL5: =AG5-AK5 -> -1 | AM5: =SUM(C5,I5,O5,U5,AA5) -> 35.5 | AN5: =IFERROR(AG5/AM5, 0) -> 0 | AO5: =SUM(H5,N5,T5,Z5,AF5) -> 0 | AP5: ELIGO | AQ5: CJ
A6: 1288 | B6: Allen Alberts(Commercial-Closer) | C6: {=_xlfn.XLOOKUP(A6,'Agents Hrs'!A:A,'Agents Hrs'!D:D,0,0)} -> 7 | G6: =IFERROR(E6/C6, 0) -> 0 | I6: {=_xlfn.XLOOKUP(A6,'Agents Hrs'!A:A,'Agents Hrs'!F:F,0,0)} -> 7 | M6: =IFERROR(K6/I6, 0) -> 0 | O6: {=_xlfn.XLOOKUP(A6,'Agents Hrs'!A:A,'Agents Hrs'!H:H,0,0)} -> 7.5 | P6: 0 | Q6: 0 | S6: =IFERROR(Q6/O6, 0) -> 0 | U6: {=_xlfn.XLOOKUP(A6,'Agents Hrs'!A:A,'Agents Hrs'!J:J,0,0)} -> 7.25 | W6: 0 | Y6: =IFERROR(W6/U6, 0) -> 0 | AA6: {=_xlfn.XLOOKUP(A6,'Agents Hrs'!A:A,'Agents Hrs'!L:L,0,0)} -> 6.25 | AB6: 0 | AC6: 0 | AE6: =IFERROR(AC6/AA6, 0) -> 0 | AG6: =SUM(E6,K6,Q6,W6,AC6) -> 0 | AI6: =SUM(F6,L6,R6,X6,AD6) -> 0 | AJ6: =AG6-AH6 -> 0 | AK6: 4 | AL6: =AG6-AK6 -> -4 | AM6: =SUM(C6,I6,O6,U6,AA6) -> 35 | AN6: =IFERROR(AG6/AM6, 0) -> 0 | AO6: =SUM(H6,N6,T6,Z6,AF6) -> 0 | AP6: ELIGO | AQ6: CJ
A7: 1175 | B7: Kenticka Tate (Remote)(Commercial) | C7: {=_xlfn.XLOOKUP(A7,'Agents Hrs'!A:A,'Agents Hrs'!D:D,0,0)} -> 8 | E7: 2 | G7: =IFERROR(E7/C7, 0) -> 0.25 | I7: {=_xlfn.XLOOKUP(A7,'Agents Hrs'!A:A,'Agents Hrs'!F:F,0,0)} -> 8 | M7: =IFERROR(K7/I7, 0) -> 0 | O7: {=_xlfn.XLOOKUP(A7,'Agents Hrs'!A:A,'Agents Hrs'!H:H,0,0)} -> 7.25 | P7: 0 | Q7: 0 | S7: =IFERROR(Q7/O7, 0) -> 0 | U7: {=_xlfn.XLOOKUP(A7,'Agents Hrs'!A:A,'Agents Hrs'!J:J,0,0)} -> 7.75 | V7: 1 | W7: 1 | Y7: =IFERROR(W7/U7, 0) -> 0.12903226 | AA7: {=_xlfn.XLOOKUP(A7,'Agents Hrs'!A:A,'Agents Hrs'!L:L,0,0)} -> 7.75 | AB7: 2 | AC7: 1 | AE7: =IFERROR(AC7/AA7, 0) -> 0.12903226 | AG7: =SUM(E7,K7,Q7,W7,AC7) -> 4 | AI7: =SUM(F7,L7,R7,X7,AD7) -> 0 | AJ7: =AG7-AH7 -> 4 | AK7: 4 | AL7: =AG7-AK7 -> 0 | AM7: =SUM(C7,I7,O7,U7,AA7) -> 38.75 | AN7: =IFERROR(AG7/AM7, 0) -> 0.10322581 | AO7: =SUM(H7,N7,T7,Z7,AF7) -> 0 | AP7: ELIGO | AQ7: CJ
A8: 1294 | B8: Brandy Paton (Commercial) | C8: {=_xlfn.XLOOKUP(A8,'Agents Hrs'!A:A,'Agents Hrs'!D:D,0,0)} -> 7 | G8: =IFERROR(E8/C8, 0) -> 0 | I8: {=_xlfn.XLOOKUP(A8,'Agents Hrs'!A:A,'Agents Hrs'!F:F,0,0)} -> 7.5 | K8: 1 | M8: =IFERROR(K8/I8, 0) -> 0.13333333 | O8: {=_xlfn.XLOOKUP(A8,'Agents Hrs'!A:A,'Agents Hrs'!H:H,0,0)} -> 7 | P8: 0 | Q8: 0 | S8: =IFERROR(Q8/O8, 0) -> 0 | U8: {=_xlfn.XLOOKUP(A8,'Agents Hrs'!A:A,'Agents Hrs'!J:J,0,0)} -> 7 | W8: 0 | Y8: =IFERROR(W8/U8, 0) -> 0 | AA8: {=_xlfn.XLOOKUP(A8,'Agents Hrs'!A:A,'Agents Hrs'!L:L,0,0)} -> 7.75 | AB8: 0 | AC8: 0 | AE8: =IFERROR(AC8/AA8, 0) -> 0 | AG8: =SUM(E8,K8,Q8,W8,AC8) -> 1 | AI8: =SUM(F8,L8,R8,X8,AD8) -> 0 | AJ8: =AG8-AH8 -> 1 | AK8: 1 | AL8: =AG8-AK8 -> 0 | AM8: =SUM(C8,I8,O8,U8,AA8) -> 36.25 | AN8: =IFERROR(AG8/AM8, 0) -> 0.027586207 | AO8: =SUM(H8,N8,T8,Z8,AF8) -> 0 | AP8: ELIGO | AQ8: CJ
A9: 1280 | B9: Ashlee Franks (Commercial) | C9: {=_xlfn.XLOOKUP(A9,'Agents Hrs'!A:A,'Agents Hrs'!D:D,0,0)} -> 6.5 | G9: =IFERROR(E9/C9, 0) -> 0 | I9: {=_xlfn.XLOOKUP(A9,'Agents Hrs'!A:A,'Agents Hrs'!F:F,0,0)} -> 6.5 | M9: =IFERROR(K9/I9, 0) -> 0 | O9: {=_xlfn.XLOOKUP(A9,'Agents Hrs'!A:A,'Agents Hrs'!H:H,0,0)} -> 6.75 | P9: 4 | Q9: 4 | S9: =IFERROR(Q9/O9, 0) -> 0.59259259 | U9: {=_xlfn.XLOOKUP(A9,'Agents Hrs'!A:A,'Agents Hrs'!J:J,0,0)} -> 6.5 | W9: 0 | Y9: =IFERROR(W9/U9, 0) -> 0 | AA9: {=_xlfn.XLOOKUP(A9,'Agents Hrs'!A:A,'Agents Hrs'!L:L,0,0)} -> 6 | AB9: 0 | AC9: 1 | AE9: =IFERROR(AC9/AA9, 0) -> 0.16666667 | AG9: =SUM(E9,K9,Q9,W9,AC9) -> 5 | AI9: =SUM(F9,L9,R9,X9,AD9) -> 0 | AJ9: =AG9-AH9 -> 5 | AK9: 0 | AL9: =AG9-AK9 -> 5 | AM9: =SUM(C9,I9,O9,U9,AA9) -> 32.25 | AN9: =IFERROR(AG9/AM9, 0) -> 0.15503876 | AO9: =SUM(H9,N9,T9,Z9,AF9) -> 0 | AP9: ELIGO | AQ9: CJ
A10: 1298 | B10: Shelby Lewis (Commercial) | C10: {=_xlfn.XLOOKUP(A10,'Agents Hrs'!A:A,'Agents Hrs'!D:D,0,0)} -> 7 | G10: =IFERROR(E10/C10, 0) -> 0 | I10: {=_xlfn.XLOOKUP(A10,'Agents Hrs'!A:A,'Agents Hrs'!F:F,0,0)} -> 7 | K10: 0 | M10: =IFERROR(K10/I10, 0) -> 0 | O10: {=_xlfn.XLOOKUP(A10,'Agents Hrs'!A:A,'Agents Hrs'!H:H,0,0)} -> 7.5 | P10: 2 | Q10: 0 | S10: =IFERROR(Q10/O10, 0) -> 0 | U10: {=_xlfn.XLOOKUP(A10,'Agents Hrs'!A:A,'Agents Hrs'!J:J,0,0)} -> 7.75 | V10: 1 | W10: 1 | Y10: =IFERROR(W10/U10, 0) -> 0.12903226 | AA10: {=_xlfn.XLOOKUP(A10,'Agents Hrs'!A:A,'Agents Hrs'!L:L,0,0)} -> 7.5 | AB10: 1 | AC10: 0 | AE10: =IFERROR(AC10/AA10, 0) -> 0 | AG10: =SUM(E10,K10,Q10,W10,AC10) -> 1 | AI10: =SUM(F10,L10,R10,X10,AD10) -> 0 | AJ10: =AG10-AH10 -> 1 | AK10: 1 | AL10: =AG10-AK10 -> 0 | AM10: =SUM(C10,I10,O10,U10,AA10) -> 36.75 | AN10: =IFERROR(AG10/AM10, 0) -> 0.027210884 | AO10: =SUM(H10,N10,T10,Z10,AF10) -> 0 | AP10: ELIGO | AQ10: CJ
A11: 1301 | B11: Albert Williams (Commercial) | C11: {=_xlfn.XLOOKUP(A11,'Agents Hrs'!A:A,'Agents Hrs'!D:D,0,0)} -> 0 | G11: =IFERROR(E11/C11, 0) -> 0 | I11: {=_xlfn.XLOOKUP(A11,'Agents Hrs'!A:A,'Agents Hrs'!F:F,0,0)} -> 6.5 | M11: =IFERROR(K11/I11, 0) -> 0 | O11: {=_xlfn.XLOOKUP(A11,'Agents Hrs'!A:A,'Agents Hrs'!H:H,0,0)} -> 7 | P11: 0 | Q11: 0 | S11: =IFERROR(Q11/O11, 0) -> 0 | U11: {=_xlfn.XLOOKUP(A11,'Agents Hrs'!A:A,'Agents Hrs'!J:J,0,0)} -> 6.5 | W11: 0 | Y11: =IFERROR(W11/U11, 0) -> 0 | AA11: {=_xlfn.XLOOKUP(A11,'Agents Hrs'!A:A,'Agents Hrs'!L:L,0,0)} -> 7.5 | AB11: 0 | AC11: 0 | AE11: =IFERROR(AC11/AA11, 0) -> 0 | AG11: =SUM(E11,K11,Q11,W11,AC11) -> 0 | AI11: =SUM(F11,L11,R11,X11,AD11) -> 0 | AJ11: =AG11-AH11 -> 0 | AK11: 1 | AL11: =AG11-AK11 -> -1 | AM11: =SUM(C11,I11,O11,U11,AA11) -> 27.5 | AN11: =IFERROR(AG11/AM11, 0) -> 0 | AO11: =SUM(H11,N11,T11,Z11,AF11) -> 0 | AP11: ELIGO | AQ11: CJ
A12: 1290 | B12: Abigail Gambino (Commercial-Closer) | C12: {=_xlfn.XLOOKUP(A12,'Agents Hrs'!A:A,'Agents Hrs'!D:D,0,0)} -> 0 | G12: =IFERROR(E12/C12, 0) -> 0 | I12: {=_xlfn.XLOOKUP(A12,'Agents Hrs'!A:A,'Agents Hrs'!F:F,0,0)} -> 0 | K12: 1 | M12: =IFERROR(K12/I12, 0) -> 0 | O12: {=_xlfn.XLOOKUP(A12,'Agents Hrs'!A:A,'Agents Hrs'!H:H,0,0)} -> 0 | P12: 0 | Q12: 0 | S12: =IFERROR(Q12/O12, 0) -> 0 | U12: {=_xlfn.XLOOKUP(A12,'Agents Hrs'!A:A,'Agents Hrs'!J:J,0,0)} -> 0 | W12: 0 | Y12: =IFERROR(W12/U12, 0) -> 0 | AA12: {=_xlfn.XLOOKUP(A12,'Agents Hrs'!A:A,'Agents Hrs'!L:L,0,0)} -> 0 | AB12: 0 | AC12: 0 | AE12: =IFERROR(AC12/AA12, 0) -> 0 | AG12: =SUM(E12,K12,Q12,W12,AC12) -> 1 | AI12: =SUM(F12,L12,R12,X12,AD12) -> 0 | AJ12: =AG12-AH12 -> 1 | AK12: 5 | AL12: =AG12-AK12 -> -4 | AM12: =SUM(C12,I12,O12,U12,AA12) -> 0 | AN12: =IFERROR(AG12/AM12, 0) -> 0 | AO12: =SUM(H12,N12,T12,Z12,AF12) -> 0 | AP12: ELIGO | AQ12: CJ
A13: 1151 | B13: CJ Jackson (Manager/Closer) | C13: {=_xlfn.XLOOKUP(A13,'Agents Hrs'!A:A,'Agents Hrs'!D:D,0,0)} -> 0 | G13: =IFERROR(E13/C13, 0) -> 0 | I13: {=_xlfn.XLOOKUP(A13,'Agents Hrs'!A:A,'Agents Hrs'!F:F,0,0)} -> 0 | K13: 1 | M13: =IFERROR(K13/I13, 0) -> 0 | O13: {=_xlfn.XLOOKUP(A13,'Agents Hrs'!A:A,'Agents Hrs'!H:H,0,0)} -> 0 | P13: 0 | Q13: 0 | S13: =IFERROR(Q13/O13, 0) -> 0 | U13: {=_xlfn.XLOOKUP(A13,'Agents Hrs'!A:A,'Agents Hrs'!J:J,0,0)} -> 0 | W13: 0 | Y13: =IFERROR(W13/U13, 0) -> 0 | AA13: {=_xlfn.XLOOKUP(A13,'Agents Hrs'!A:A,'Agents Hrs'!L:L,0,0)} -> 0 | AB13: 0 | AC13: 0 | AE13: =IFERROR(AC13/AA13, 0) -> 0 | AG13: =SUM(E13,K13,Q13,W13,AC13) -> 1 | AI13: =SUM(F13,L13,R13,X13,AD13) -> 0 | AJ13: =AG13-AH13 -> 1 | AK13: 0 | AL13: =AG13-AK13 -> 1 | AM13: =SUM(C13,I13,O13,U13,AA13) -> 0 | AN13: =IFERROR(AG13/AM13, 0) -> 0 | AO13: =SUM(H13,N13,T13,Z13,AF13) -> 0 | AP13: ELIGO | AQ13: CJ
A14: 1300 | B14: Neil Singhal (Commercial) | C14: {=_xlfn.XLOOKUP(A14,'Agents Hrs'!A:A,'Agents Hrs'!D:D,0,0)} -> 8 | E14: 2 | G14: =IFERROR(E14/C14, 0) -> 0.25 | I14: {=_xlfn.XLOOKUP(A14,'Agents Hrs'!A:A,'Agents Hrs'!F:F,0,0)} -> 8 | M14: =IFERROR(K14/I14, 0) -> 0 | O14: {=_xlfn.XLOOKUP(A14,'Agents Hrs'!A:A,'Agents Hrs'!H:H,0,0)} -> 7.25 | P14: 0 | Q14: 14 | S14: =IFERROR(Q14/O14, 0) -> 1.9310345 | U14: {=_xlfn.XLOOKUP(A14,'Agents Hrs'!A:A,'Agents Hrs'!J:J,0,0)} -> 7.5 | W14: 0 | Y14: =IFERROR(W14/U14, 0) -> 0 | AA14: {=_xlfn.XLOOKUP(A14,'Agents Hrs'!A:A,'Agents Hrs'!L:L,0,0)} -> 7.5 | AB14: 0 | AC14: 0 | AE14: =IFERROR(AC14/AA14, 0) -> 0 | AG14: =SUM(E14,K14,Q14,W14,AC14) -> 16 | AI14: =SUM(F14,L14,R14,X14,AD14) -> 0 | AJ14: =AG14-AH14 -> 16 | AK14: 5 | AL14: =AG14-AK14 -> 11 | AM14: =SUM(C14,I14,O14,U14,AA14) -> 38.25 | AN14: =IFERROR(AG14/AM14, 0) -> 0.41830065 | AO14: =SUM(H14,N14,T14,Z14,AF14) -> 0 | AP14: ELIGO | AQ14: CJ
C15: {=_xlfn.XLOOKUP(A15,'Agents Hrs'!A:A,'Agents Hrs'!D:D,0,0)} -> 0 | G15: =IFERROR(E15/C15, 0) -> 0 | I15: {=_xlfn.XLOOKUP(A15,'Agents Hrs'!A:A,'Agents Hrs'!F:F,0,0)} -> 0 | M15: =IFERROR(K15/I15, 0) -> 0 | O15: {=_xlfn.XLOOKUP(A15,'Agents Hrs'!A:A,'Agents Hrs'!H:H,0,0)} -> 0 | P15: 0 | S15: =IFERROR(Q15/O15, 0) -> 0 | U15: {=_xlfn.XLOOKUP(A15,'Agents Hrs'!A:A,'Agents Hrs'!J:J,0,0)} -> 0 | Y15: =IFERROR(W15/U15, 0) -> 0 | AA15: {=_xlfn.XLOOKUP(A15,'Agents Hrs'!A:A,'Agents Hrs'!L:L,0,0)} -> 0 | AB15: 0 | AC15: 0 | AE15: =IFERROR(AC15/AA15, 0) -> 0 | AG15: =SUM(E15,K15,Q15,W15,AC15) -> 0 | AI15: =SUM(F15,L15,R15,X15,AD15) -> 0 | AJ15: =AG15-AH15 -> 0 | AL15: =AG15-AK15 -> 0 | AM15: =SUM(C15,I15,O15,U15,AA15) -> 0 | AN15: =IFERROR(AG15/AM15, 0) -> 0 | AO15: =SUM(H15,N15,T15,Z15,AF15) -> 0 | AP15: ELIGO | AQ15: CJ
B16: Total | C16: =SUM(C3:C15) -> 64.5 | D16: =SUM(D3:D15) -> 0 | E16: =SUM(E3:E15) -> 5 | G16: =IFERROR(E16/C16, 0) -> 0.07751938 | H16: =SUM(H3:H15) -> 0 | I16: =SUM(I3:I15) -> 72 | J16: =SUM(J3:J15) -> 0 | K16: =SUM(K3:K15) -> 4 | M16: =IFERROR(K16/I16, 0) -> 0.055555556 | N16: =SUM(N3:N15) -> 0 | O16: =SUM(O3:O15) -> 72 | P16: =SUM(P3:P15) -> 9 | Q16: =SUM(Q3:Q15) -> 21 | S16: =IFERROR(Q16/O16, 0) -> 0.29166667 | T16: =SUM(T3:T15) -> 0 | U16: =SUM(U3:U15) -> 71.5 | V16: =SUM(V3:V15) -> 4 | W16: =SUM(W3:W15) -> 2 | Y16: =IFERROR(W16/U16, 0) -> 0.027972028 | Z16: =SUM(Z3:Z15) -> 0 | AA16: =SUM(AA3:AA15) -> 68.65 | AB16: =SUM(AB3:AB15) -> 4 | AC16: =SUM(AC3:AC15) -> 2 | AE16: =IFERROR(AC16/AA16, 0) -> 0.029133285 | AF16: =SUM(AF3:AF15) -> 0 | AG16: =SUM(AG3:AG15) -> 34 | AI16: =SUM(AI3:AI15) -> 0 | AJ16: =AG16-AH16 -> 34 | AK16: 15 | AL16: =AG16-AK16 -> 19 | AM16: =SUM(AM3:AM15) -> 348.65 | AN16: =IFERROR(AG16/AM16, 0) -> 0.097519002 | AO16: =SUM(AO3:AO15) -> 0 | AP16: ELIGO | AQ16: CJ
B17: TRAINING (in house)
A18: Rep # | B18: Rep Name
AG19: =SUM(Q19:AC19) -> 0 | AJ19: =AG19-AH19 -> 0 | AK19: 0 | AL19: =AG19-AK19 -> 0 | AP19: ELIGO | AQ19: CJ
AG20: =SUM(Q20:AC20) -> 0 | AJ20: =AG20-AH20 -> 0 | AK20: 0 | AL20: =AG20-AK20 -> 0 | AP20: ELIGO | AQ20: CJ
AG21: =SUM(Q21:AC21) -> 0 | AJ21: =AG21-AH21 -> 0 | AK21: 0 | AL21: =AG21-AK21 -> 0 | AP21: ELIGO | AQ21: CJ
B22: Total | D22: =SUM(D19:D20) -> 0 | E22: =SUM(E19:E20) -> 0 | J22: =SUM(J19:J20) -> 0 | K22: =SUM(K19:K20) -> 0 | P22: =SUM(P19:P20) -> 0 | Q22: =SUM(Q19:Q20) -> 0 | V22: =SUM(V19:V20) -> 0 | W22: =SUM(W19:W20) -> 0 | AB22: =SUM(AB19:AB20) -> 0 | AC22: =SUM(AC19:AC20) -> 0 | AG22: =SUM(AG19:AG20) -> 0 | AH22: =SUM(AH19:AH20) -> 0 | AJ22: =SUM(AJ19:AJ20) -> 0 | AK22: =SUM(AK19:AK20) -> 0 | AL22: =AG22-AK22 -> 0 | AP22: ELIGO | AQ22: CJ
B23: Admin Staff
AG24: =SUM(Q24:AC24) -> 0 | AJ24: =AG24-AH24 -> 0 | AK24: 0 | AL24: =AG24-AK24 -> 0 | AP24: ELIGO | AQ24: CJ
AG25: =SUM(Q25:AC25) -> 0 | AJ25: =AG25-AH25 -> 0 | AK25: 0 | AL25: =AG25-AK25 -> 0 | AP25: ELIGO | AQ25: CJ
AG26: =SUM(Q26:AC26) -> 0 | AJ26: =AG26-AH26 -> 0 | AK26: 0 | AL26: =AG26-AK26 -> 0 | AP26: ELIGO | AQ26: CJ
AG27: =SUM(Q27:AC27) -> 0 | AJ27: =AG27-AH27 -> 0 | AK27: 0 | AL27: =AG27-AK27 -> 0 | AP27: ELIGO | AQ27: CJ
B28: Total | D28: =D16 -> 0 | E28: =E16 -> 5 | J28: =J16 -> 0 | K28: =K16 -> 4 | P28: =P16 -> 9 | Q28: =Q16 -> 21 | V28: =V16 -> 4 | W28: =W16 -> 2 | AB28: =AB16 -> 4 | AC28: =AC16 -> 2 | AG28: =AG16 -> 34 | AH28: =AH16 -> 0 | AJ28: =AJ16 -> 34 | AK28: =AK16 -> 15 | AL28: =AG28-AK28 -> 19
B29: Last Week | Q29: 2 | V29: 1 | W29: 2 | AB29: 2 | AC29: 0 | AG29: 7
B30: Difference | Q30: =Q28-Q29 -> 19 | V30: =V28-V29 -> 3 | W30: =W28-W29 -> 0 | AB30: =AB28-AB29 -> 2 | AC30: =AC28-AC29 -> 2 | AG30: =AG28-AG29 -> 27 | AS30: a

Sheet Agents Hrs
B1: Eligo Energy Hours Commercial
A3: Rep # | B3: Name | C3: Monday | D3: Hrs | E3: Tuesday | F3: Hrs | G3: Wednesday | H3: Hrs | I3: Thursday | J3: Hrs | K3: Friday | L3: Hrs | M3: TOTAL
A5: 1290 | B5: Abigail Gambino (Commercial) | C5: NH | D5: 0 | E5: NH | F5: 0 | G5: NH | H5: 0 | I5: NH | J5: 0 | K5: NH | L5: 0 | M5: =SUM(D5,F5,H5,J5,L5) -> 0
A6: 1288 | B6: Allen Alberts | C6: 830,11-1130-5 | D6: 7 | E6: 830,11-1130-5 | F6: 7 | G6: 930-5 | H6: 7.5 | I6: 830-145-230-5 | J6: 7.25 | K6: 900-145-2-430 | L6: 6.25 | M6: =SUM(D6,F6,H6,J6,L6) -> 35
A7: 1294 | B7: Brandy Paton | C7: 830,10-1030-5 | D7: 7 | E7: 830,1130-1145-5 | F7: 7.5 | G7: 900,1130-12-5 | H7: 7 | I7: 900-12-1230-5 | J7: 7 | K7: 830-1130-1145-5 | L7: 7.75 | M7: =SUM(D7,F7,H7,J7,L7) -> 36.25
A8: 1292 | B8: Jakarta Hunter (Commercial) | C8: 830,930-10-5 | D8: 7 | E8: 900-5 | F8: 7 | G8: 830-5 | H8: 8 | I8: 830-1030-1045-5 | J8: 7.75 | K8: 1245-430 | L8: 3.15 | M8: =SUM(D8,F8,H8,J8,L8) -> 32.9
A9: 1175 | B9: Kenticka Tate (Remote)(Commercial) | C9: 830-5 | D9: 8 | E9: 830-5 | F9: 8 | G9: 900-315,330-5 | H9: 7.25 | I9: 830-1030-1045-5 | J9: 7.75 | K9: 830-145-2-5 | L9: 7.75 | M9: =SUM(D9,F9,H9,J9,L9) -> 38.75
A10: 1295 | B10: Luis Buitrago | C10: 830,11-1130-5 | D10: 7 | E10: 900-5 | F10: 7 | G10: 900,1130-12-5 | H10: 7 | I10: 900-1130-1215-5 | J10: 6.75 | K10: 830-145-2-5 | L10: 7.75 | M10: =SUM(D10,F10,H10,J10,L10) -> 35.5
A11: 1291 | B11: Raven Mitchell (Commercial) | C11: 830,9-930-5 | D11: 7 | E11: 840-1115,1130-5 | F11: 7.5 | G11: 900-1115,1130-12-5 | H11: 6.75 | I11: 900-1130-1215-5 | J11: 6.75 | K11: 900-915-5 | L11: 7.5 | M11: =SUM(D11,F11,H11,J11,L11) -> 35.5
A12: 1298 | B12: Shelby Lewis | C12: 830,10-1030-5 | D12: 7 | E12: 900-5 | F12: 7 | G12: 830-3,330-5 | H12: 7.5 | I12: 830-1030-1045-5 | J12: 7.75 | K12: 900-915-5 | L12: 7.5 | M12: =SUM(D12,F12,H12,J12,L12) -> 36.75
A13: 1300 | B13: Neil Singhal | C13: 830-5 | D13: 8 | E13: 830-5 | F13: 8 | G13: 830,115-2-5 | H13: 7.25 | I13: 830-230-300-5 | J13: 7.5 | K13: 900-915-5 | L13: 7.5 | M13: =SUM(D13,F13,H13,J13,L13) -> 38.25
A14: 1301 | B14: Albert Williams (Commercial) | C14: OUT | D14: 0 | E14: 830-1115,1145-5 | F14: 6.5 | G14: 900-1130-12-5 | H14: 7 | I14: 900-1130-1230-5 | J14: 6.5 | K14: 900-915-5 | L14: 7.5 | M14: =SUM(D14,F14,H14,J14,L14) -> 27.5
A15: 1280 | B15: Ashlee Franks | C15: 830,900-930,1115,1130-5 | D15: 6.5 | E15: 900-10,1115-5 | F15: 6.5 | G15: 900-1145,1-5 | H15: 6.75 | I15: 900-1130-1230-5 | J15: 6.5 | K15: 900-915-200-215-5 | L15: 6 | M15: =SUM(D15,F15,H15,J15,L15) -> 32.25
M16: =SUM(D16,F16,H16,J16,L16) -> 0
M17: =SUM(D17,F17,H17,J17,L17) -> 0
A18: TOTAL | B18: HOURS | D18: =SUM(D5:D17) -> 64.5 | F18: =SUM(F4:F17) -> 72 | H18: =SUM(H5:H17) -> 72 | J18: =SUM(J5:J17) -> 71.5 | L18: =SUM(L5:L17) -> 68.65 | M18: =SUM(D18,F18,H18,J18,L18,#REF!) -> #REF!
A19: Remote Agents
M20: =SUM(D20,F20,H20,J20,L20) -> 0
M21: =SUM(D21,F21,H21,J21,L21) -> 0
M22: =SUM(D22,F22,H22,J22,L22) -> 0
M23: =SUM(D23,F23,H23,J23,L23) -> 0
M24: =SUM(D24,F24,H24,J24,L24) -> 0
M25: =SUM(D25,F25,H25,J25,L25) -> 0
M26: =SUM(D26,F26,H26,J26,L26) -> 0
M27: =SUM(D27,F27,H27,J27,L27) -> 0
M28: =SUM(D28,F28,H28,J28,L28) -> 0
M29: =SUM(D29,F29,H29,J29,L29) -> 0
M30: =SUM(D30,F30,H30,J30,L30) -> 0
M31: =SUM(D31,F31,H31,J31,L31) -> 0
A32: Trainees
M33: =SUM(D33,F33,H33,J33,L33) -> 0
M34: =SUM(D34,F34,H34,J34,L34) -> 0
M35: =SUM(D35,F35,H35,J35,L35) -> 0
M36: =SUM(D36,F36,H36,J36,L36) -> 0
M37: =SUM(D37,F37,H37,J37,L37) -> 0
A38: Night Reps
M39: =SUM(D39,F39,H39,J39,L39) -> 0
M40: =SUM(D40,F40,H40,J40,L40) -> 0
M41: =SUM(D41,F41,H41,J41,L41) -> 0
A42: TOTAL | B42: HOURS | D42: =SUM(D20:D41,D5:D17) -> 64.5 | F42: =SUM(F20:F41,F5:F17) -> 72 | H42: =SUM(H20:H41,H5:H17) -> 72 | J42: =SUM(J20:J41,J5:J17) -> 71.5 | L42: =SUM(L20:L41,L5:L17) -> 68.65 | M42: =SUM(D42,F42,H42,J42,L42) -> 348.65
...

Sheet Commercial Agent-Day
A1: Commercial — Sales & Fronts by Agent, by Day
C2: FRONTS | J2: SALES (CLOSES)
A3: Rep # | B3: Rep Name | C3: Mon | D3: Tue | E3: Wed | F3: Thu | G3: Fri | H3: Front Total | J3: Mon | K3: Tue | L3: Wed | M3: Thu | N3: Fri | O3: Sales Total | P3: Grand Total (Fronts + Sales)
A4: 1291 | B4: Raven Mitchell | C4: {=IFERROR(INDEX(Commercial!D$3:D$15,MATCH($A4,Commercial!$A$3:$A$15,0)),0)} -> 0 | D4: {=IFERROR(INDEX(Commercial!J$3:J$15,MATCH($A4,Commercial!$A$3:$A$15,0)),0)} -> 0 | E4: {=IFERROR(INDEX(Commercial!P$3:P$15,MATCH($A4,Commercial!$A$3:$A$15,0)),0)} -> 3 | F4: {=IFERROR(INDEX(Commercial!V$3:V$15,MATCH($A4,Commercial!$A$3:$A$15,0)),0)} -> 2 | G4: {=IFERROR(INDEX(Commercial!AB$3:AB$15,MATCH($A4,Commercial!$A$3:$A$15,0)),0)} -> 1 | H4: =SUM(C4:G4) -> 6 | J4: {=IFERROR(INDEX(Commercial!E$3:E$15,MATCH($A4,Commercial!$A$3:$A$15,0)),0)} -> 0 | K4: {=IFERROR(INDEX(Commercial!K$3:K$15,MATCH($A4,Commercial!$A$3:$A$15,0)),0)} -> 1 | L4: {=IFERROR(INDEX(Commercial!Q$3:Q$15,MATCH($A4,Commercial!$A$3:$A$15,0)),0)} -> 3 | M4: {=IFERROR(INDEX(Commercial!W$3:W$15,MATCH($A4,Commercial!$A$3:$A$15,0)),0)} -> 0 | N4: {=IFERROR(INDEX(Commercial!AC$3:AC$15,MATCH($A4,Commercial!$A$3:$A$15,0)),0)} -> 0 | O4: =SUM(J4:N4) -> 4 | P4: =H4+O4 -> 10
A5: 1292 | B5: Jakarta Hunter | C5: {=IFERROR(INDEX(Commercial!D$3:D$15,MATCH($A5,Commercial!$A$3:$A$15,0)),0)} -> 0 | D5: {=IFERROR(INDEX(Commercial!J$3:J$15,MATCH($A5,Commercial!$A$3:$A$15,0)),0)} -> 0 | E5: {=IFERROR(INDEX(Commercial!P$3:P$15,MATCH($A5,Commercial!$A$3:$A$15,0)),0)} -> 0 | F5: {=IFERROR(INDEX(Commercial!V$3:V$15,MATCH($A5,Commercial!$A$3:$A$15,0)),0)} -> 0 | G5: {=IFERROR(INDEX(Commercial!AB$3:AB$15,MATCH($A5,Commercial!$A$3:$A$15,0)),0)} -> 0 | H5: =SUM(C5:G5) -> 0 | J5: {=IFERROR(INDEX(Commercial!E$3:E$15,MATCH($A5,Commercial!$A$3:$A$15,0)),0)} -> 1 | K5: {=IFERROR(INDEX(Commercial!K$3:K$15,MATCH($A5,Commercial!$A$3:$A$15,0)),0)} -> 0 | L5: {=IFERROR(INDEX(Commercial!Q$3:Q$15,MATCH($A5,Commercial!$A$3:$A$15,0)),0)} -> 0 | M5: {=IFERROR(INDEX(Commercial!W$3:W$15,MATCH($A5,Commercial!$A$3:$A$15,0)),0)} -> 0 | N5: {=IFERROR(INDEX(Commercial!AC$3:AC$15,MATCH($A5,Commercial!$A$3:$A$15,0)),0)} -> 0 | O5: =SUM(J5:N5) -> 1 | P5: =H5+O5 -> 1
A6: 1295 | B6: Luis Buitrago | C6: {=IFERROR(INDEX(Commercial!D$3:D$15,MATCH($A6,Commercial!$A$3:$A$15,0)),0)} -> 0 | D6: {=IFERROR(INDEX(Commercial!J$3:J$15,MATCH($A6,Commercial!$A$3:$A$15,0)),0)} -> 0 | E6: {=IFERROR(INDEX(Commercial!P$3:P$15,MATCH($A6,Commercial!$A$3:$A$15,0)),0)} -> 0 | F6: {=IFERROR(INDEX(Commercial!V$3:V$15,MATCH($A6,Commercial!$A$3:$A$15,0)),0)} -> 0 | G6: {=IFERROR(INDEX(Commercial!AB$3:AB$15,MATCH($A6,Commercial!$A$3:$A$15,0)),0)} -> 0 | H6: =SUM(C6:G6) -> 0 | J6: {=IFERROR(INDEX(Commercial!E$3:E$15,MATCH($A6,Commercial!$A$3:$A$15,0)),0)} -> 0 | K6: {=IFERROR(INDEX(Commercial!K$3:K$15,MATCH($A6,Commercial!$A$3:$A$15,0)),0)} -> 0 | L6: {=IFERROR(INDEX(Commercial!Q$3:Q$15,MATCH($A6,Commercial!$A$3:$A$15,0)),0)} -> 0 | M6: {=IFERROR(INDEX(Commercial!W$3:W$15,MATCH($A6,Commercial!$A$3:$A$15,0)),0)} -> 0 | N6: {=IFERROR(INDEX(Commercial!AC$3:AC$15,MATCH($A6,Commercial!$A$3:$A$15,0)),0)} -> 0 | O6: =SUM(J6:N6) -> 0 | P6: =H6+O6 -> 0
A7: 1290 | B7: Abigail Gambino | C7: {=IFERROR(INDEX(Commercial!D$3:D$15,MATCH($A7,Commercial!$A$3:$A$15,0)),0)} -> 0 | D7: {=IFERROR(INDEX(Commercial!J$3:J$15,MATCH($A7,Commercial!$A$3:$A$15,0)),0)} -> 0 | E7: {=IFERROR(INDEX(Commercial!P$3:P$15,MATCH($A7,Commercial!$A$3:$A$15,0)),0)} -> 0 | F7: {=IFERROR(INDEX(Commercial!V$3:V$15,MATCH($A7,Commercial!$A$3:$A$15,0)),0)} -> 0 | G7: {=IFERROR(INDEX(Commercial!AB$3:AB$15,MATCH($A7,Commercial!$A$3:$A$15,0)),0)} -> 0 | H7: =SUM(C7:G7) -> 0 | J7: {=IFERROR(INDEX(Commercial!E$3:E$15,MATCH($A7,Commercial!$A$3:$A$15,0)),0)} -> 0 | K7: {=IFERROR(INDEX(Commercial!K$3:K$15,MATCH($A7,Commercial!$A$3:$A$15,0)),0)} -> 1 | L7: {=IFERROR(INDEX(Commercial!Q$3:Q$15,MATCH($A7,Commercial!$A$3:$A$15,0)),0)} -> 0 | M7: {=IFERROR(INDEX(Commercial!W$3:W$15,MATCH($A7,Commercial!$A$3:$A$15,0)),0)} -> 0 | N7: {=IFERROR(INDEX(Commercial!AC$3:AC$15,MATCH($A7,Commercial!$A$3:$A$15,0)),0)} -> 0 | O7: =SUM(J7:N7) -> 1 | P7: =H7+O7 -> 1
A8: 1288 | B8: Allen Alberts | C8: {=IFERROR(INDEX(Commercial!D$3:D$15,MATCH($A8,Commercial!$A$3:$A$15,0)),0)} -> 0 | D8: {=IFERROR(INDEX(Commercial!J$3:J$15,MATCH($A8,Commercial!$A$3:$A$15,0)),0)} -> 0 | E8: {=IFERROR(INDEX(Commercial!P$3:P$15,MATCH($A8,Commercial!$A$3:$A$15,0)),0)} -> 0 | F8: {=IFERROR(INDEX(Commercial!V$3:V$15,MATCH($A8,Commercial!$A$3:$A$15,0)),0)} -> 0 | G8: {=IFERROR(INDEX(Commercial!AB$3:AB$15,MATCH($A8,Commercial!$A$3:$A$15,0)),0)} -> 0 | H8: =SUM(C8:G8) -> 0 | J8: {=IFERROR(INDEX(Commercial!E$3:E$15,MATCH($A8,Commercial!$A$3:$A$15,0)),0)} -> 0 | K8: {=IFERROR(INDEX(Commercial!K$3:K$15,MATCH($A8,Commercial!$A$3:$A$15,0)),0)} -> 0 | L8: {=IFERROR(INDEX(Commercial!Q$3:Q$15,MATCH($A8,Commercial!$A$3:$A$15,0)),0)} -> 0 | M8: {=IFERROR(INDEX(Commercial!W$3:W$15,MATCH($A8,Commercial!$A$3:$A$15,0)),0)} -> 0 | N8: {=IFERROR(INDEX(Commercial!AC$3:AC$15,MATCH($A8,Commercial!$A$3:$A$15,0)),0)} -> 0 | O8: =SUM(J8:N8) -> 0 | P8: =H8+O8 -> 0
A9: 1175 | B9: Kenticka Tate (Remote) | C9: {=IFERROR(INDEX(Commercial!D$3:D$15,MATCH($A9,Commercial!$A$3:$A$15,0)),0)} -> 0 | D9: {=IFERROR(INDEX(Commercial!J$3:J$15,MATCH($A9,Commercial!$A$3:$A$15,0)),0)} -> 0 | E9: {=IFERROR(INDEX(Commercial!P$3:P$15,MATCH($A9,Commercial!$A$3:$A$15,0)),0)} -> 0 | F9: {=IFERROR(INDEX(Commercial!V$3:V$15,MATCH($A9,Commercial!$A$3:$A$15,0)),0)} -> 1 | G9: {=IFERROR(INDEX(Commercial!AB$3:AB$15,MATCH($A9,Commercial!$A$3:$A$15,0)),0)} -> 2 | H9: =SUM(C9:G9) -> 3 | J9: {=IFERROR(INDEX(Commercial!E$3:E$15,MATCH($A9,Commercial!$A$3:$A$15,0)),0)} -> 2 | K9: {=IFERROR(INDEX(Commercial!K$3:K$15,MATCH($A9,Commercial!$A$3:$A$15,0)),0)} -> 0 | L9: {=IFERROR(INDEX(Commercial!Q$3:Q$15,MATCH($A9,Commercial!$A$3:$A$15,0)),0)} -> 0 | M9: {=IFERROR(INDEX(Commercial!W$3:W$15,MATCH($A9,Commercial!$A$3:$A$15,0)),0)} -> 1 | N9: {=IFERROR(INDEX(Commercial!AC$3:AC$15,MATCH($A9,Commercial!$A$3:$A$15,0)),0)} -> 1 | O9: =SUM(J9:N9) -> 4 | P9: =H9+O9 -> 7
A10: 1294 | B10: Brandy Paton | C10: {=IFERROR(INDEX(Commercial!D$3:D$15,MATCH($A10,Commercial!$A$3:$A$15,0)),0)} -> 0 | D10: {=IFERROR(INDEX(Commercial!J$3:J$15,MATCH($A10,Commercial!$A$3:$A$15,0)),0)} -> 0 | E10: {=IFERROR(INDEX(Commercial!P$3:P$15,MATCH($A10,Commercial!$A$3:$A$15,0)),0)} -> 0 | F10: {=IFERROR(INDEX(Commercial!V$3:V$15,MATCH($A10,Commercial!$A$3:$A$15,0)),0)} -> 0 | G10: {=IFERROR(INDEX(Commercial!AB$3:AB$15,MATCH($A10,Commercial!$A$3:$A$15,0)),0)} -> 0 | H10: =SUM(C10:G10) -> 0 | J10: {=IFERROR(INDEX(Commercial!E$3:E$15,MATCH($A10,Commercial!$A$3:$A$15,0)),0)} -> 0 | K10: {=IFERROR(INDEX(Commercial!K$3:K$15,MATCH($A10,Commercial!$A$3:$A$15,0)),0)} -> 1 | L10: {=IFERROR(INDEX(Commercial!Q$3:Q$15,MATCH($A10,Commercial!$A$3:$A$15,0)),0)} -> 0 | M10: {=IFERROR(INDEX(Commercial!W$3:W$15,MATCH($A10,Commercial!$A$3:$A$15,0)),0)} -> 0 | N10: {=IFERROR(INDEX(Commercial!AC$3:AC$15,MATCH($A10,Commercial!$A$3:$A$15,0)),0)} -> 0 | O10: =SUM(J10:N10) -> 1 | P10: =H10+O10 -> 1
A11: 1280 | B11: Ashlee Franks | C11: {=IFERROR(INDEX(Commercial!D$3:D$15,MATCH($A11,Commercial!$A$3:$A$15,0)),0)} -> 0 | D11: {=IFERROR(INDEX(Commercial!J$3:J$15,MATCH($A11,Commercial!$A$3:$A$15,0)),0)} -> 0 | E11: {=IFERROR(INDEX(Commercial!P$3:P$15,MATCH($A11,Commercial!$A$3:$A$15,0)),0)} -> 4 | F11: {=IFERROR(INDEX(Commercial!V$3:V$15,MATCH($A11,Commercial!$A$3:$A$15,0)),0)} -> 0 | G11: {=IFERROR(INDEX(Commercial!AB$3:AB$15,MATCH($A11,Commercial!$A$3:$A$15,0)),0)} -> 0 | H11: =SUM(C11:G11) -> 4 | J11: {=IFERROR(INDEX(Commercial!E$3:E$15,MATCH($A11,Commercial!$A$3:$A$15,0)),0)} -> 0 | K11: {=IFERROR(INDEX(Commercial!K$3:K$15,MATCH($A11,Commercial!$A$3:$A$15,0)),0)} -> 0 | L11: {=IFERROR(INDEX(Commercial!Q$3:Q$15,MATCH($A11,Commercial!$A$3:$A$15,0)),0)} -> 4 | M11: {=IFERROR(INDEX(Commercial!W$3:W$15,MATCH($A11,Commercial!$A$3:$A$15,0)),0)} -> 0 | N11: {=IFERROR(INDEX(Commercial!AC$3:AC$15,MATCH($A11,Commercial!$A$3:$A$15,0)),0)} -> 1 | O11: =SUM(J11:N11) -> 5 | P11: =H11+O11 -> 9
A12: 1298 | B12: Shelby Lewis | C12: {=IFERROR(INDEX(Commercial!D$3:D$15,MATCH($A12,Commercial!$A$3:$A$15,0)),0)} -> 0 | D12: {=IFERROR(INDEX(Commercial!J$3:J$15,MATCH($A12,Commercial!$A$3:$A$15,0)),0)} -> 0 | E12: {=IFERROR(INDEX(Commercial!P$3:P$15,MATCH($A12,Commercial!$A$3:$A$15,0)),0)} -> 2 | F12: {=IFERROR(INDEX(Commercial!V$3:V$15,MATCH($A12,Commercial!$A$3:$A$15,0)),0)} -> 1 | G12: {=IFERROR(INDEX(Commercial!AB$3:AB$15,MATCH($A12,Commercial!$A$3:$A$15,0)),0)} -> 1 | H12: =SUM(C12:G12) -> 4 | J12: {=IFERROR(INDEX(Commercial!E$3:E$15,MATCH($A12,Commercial!$A$3:$A$15,0)),0)} -> 0 | K12: {=IFERROR(INDEX(Commercial!K$3:K$15,MATCH($A12,Commercial!$A$3:$A$15,0)),0)} -> 0 | L12: {=IFERROR(INDEX(Commercial!Q$3:Q$15,MATCH($A12,Commercial!$A$3:$A$15,0)),0)} -> 0 | M12: {=IFERROR(INDEX(Commercial!W$3:W$15,MATCH($A12,Commercial!$A$3:$A$15,0)),0)} -> 1 | N12: {=IFERROR(INDEX(Commercial!AC$3:AC$15,MATCH($A12,Commercial!$A$3:$A$15,0)),0)} -> 0 | O12: =SUM(J12:N12) -> 1 | P12: =H12+O12 -> 5
A13: 1300 | B13: Neil Singhal | C13: {=IFERROR(INDEX(Commercial!D$3:D$15,MATCH($A13,Commercial!$A$3:$A$15,0)),0)} -> 0 | D13: {=IFERROR(INDEX(Commercial!J$3:J$15,MATCH($A13,Commercial!$A$3:$A$15,0)),0)} -> 0 | E13: {=IFERROR(INDEX(Commercial!P$3:P$15,MATCH($A13,Commercial!$A$3:$A$15,0)),0)} -> 0 | F13: {=IFERROR(INDEX(Commercial!V$3:V$15,MATCH($A13,Commercial!$A$3:$A$15,0)),0)} -> 0 | G13: {=IFERROR(INDEX(Commercial!AB$3:AB$15,MATCH($A13,Commercial!$A$3:$A$15,0)),0)} -> 0 | H13: =SUM(C13:G13) -> 0 | J13: {=IFERROR(INDEX(Commercial!E$3:E$15,MATCH($A13,Commercial!$A$3:$A$15,0)),0)} -> 2 | K13: {=IFERROR(INDEX(Commercial!K$3:K$15,MATCH($A13,Commercial!$A$3:$A$15,0)),0)} -> 0 | L13: {=IFERROR(INDEX(Commercial!Q$3:Q$15,MATCH($A13,Commercial!$A$3:$A$15,0)),0)} -> 14 | M13: {=IFERROR(INDEX(Commercial!W$3:W$15,MATCH($A13,Commercial!$A$3:$A$15,0)),0)} -> 0 | N13: {=IFERROR(INDEX(Commercial!AC$3:AC$15,MATCH($A13,Commercial!$A$3:$A$15,0)),0)} -> 0 | O13: =SUM(J13:N13) -> 16 | P13: =H13+O13 -> 16
A14: 1301 | B14: Albert Williams | C14: {=IFERROR(INDEX(Commercial!D$3:D$15,MATCH($A14,Commercial!$A$3:$A$15,0)),0)} -> 0 | D14: {=IFERROR(INDEX(Commercial!J$3:J$15,MATCH($A14,Commercial!$A$3:$A$15,0)),0)} -> 0 | E14: {=IFERROR(INDEX(Commercial!P$3:P$15,MATCH($A14,Commercial!$A$3:$A$15,0)),0)} -> 0 | F14: {=IFERROR(INDEX(Commercial!V$3:V$15,MATCH($A14,Commercial!$A$3:$A$15,0)),0)} -> 0 | G14: {=IFERROR(INDEX(Commercial!AB$3:AB$15,MATCH($A14,Commercial!$A$3:$A$15,0)),0)} -> 0 | H14: =SUM(C14:G14) -> 0 | J14: {=IFERROR(INDEX(Commercial!E$3:E$15,MATCH($A14,Commercial!$A$3:$A$15,0)),0)} -> 0 | K14: {=IFERROR(INDEX(Commercial!K$3:K$15,MATCH($A14,Commercial!$A$3:$A$15,0)),0)} -> 0 | L14: {=IFERROR(INDEX(Commercial!Q$3:Q$15,MATCH($A14,Commercial!$A$3:$A$15,0)),0)} -> 0 | M14: {=IFERROR(INDEX(Commercial!W$3:W$15,MATCH($A14,Commercial!$A$3:$A$15,0)),0)} -> 0 | N14: {=IFERROR(INDEX(Commercial!AC$3:AC$15,MATCH($A14,Commercial!$A$3:$A$15,0)),0)} -> 0 | O14: =SUM(J14:N14) -> 0 | P14: =H14+O14 -> 0
A15: 1151 | B15: CJ Jackson (Manager) | C15: {=IFERROR(INDEX(Commercial!D$3:D$15,MATCH($A15,Commercial!$A$3:$A$15,0)),0)} -> 0 | D15: {=IFERROR(INDEX(Commercial!J$3:J$15,MATCH($A15,Commercial!$A$3:$A$15,0)),0)} -> 0 | E15: {=IFERROR(INDEX(Commercial!P$3:P$15,MATCH($A15,Commercial!$A$3:$A$15,0)),0)} -> 0 | F15: {=IFERROR(INDEX(Commercial!V$3:V$15,MATCH($A15,Commercial!$A$3:$A$15,0)),0)} -> 0 | G15: {=IFERROR(INDEX(Commercial!AB$3:AB$15,MATCH($A15,Commercial!$A$3:$A$15,0)),0)} -> 0 | H15: =SUM(C15:G15) -> 0 | J15: {=IFERROR(INDEX(Commercial!E$3:E$15,MATCH($A15,Commercial!$A$3:$A$15,0)),0)} -> 0 | K15: {=IFERROR(INDEX(Commercial!K$3:K$15,MATCH($A15,Commercial!$A$3:$A$15,0)),0)} -> 1 | L15: {=IFERROR(INDEX(Commercial!Q$3:Q$15,MATCH($A15,Commercial!$A$3:$A$15,0)),0)} -> 0 | M15: {=IFERROR(INDEX(Commercial!W$3:W$15,MATCH($A15,Commercial!$A$3:$A$15,0)),0)} -> 0 | N15: {=IFERROR(INDEX(Commercial!AC$3:AC$15,MATCH($A15,Commercial!$A$3:$A$15,0)),0)} -> 0 | O15: =SUM(J15:N15) -> 1 | P15: =H15+O15 -> 1
B16: Total | C16: =SUM(C4:C15) -> 0 | D16: =SUM(D4:D15) -> 0 | E16: =SUM(E4:E15) -> 9 | F16: =SUM(F4:F15) -> 4 | G16: =SUM(G4:G15) -> 4 | H16: =SUM(H4:H15) -> 17 | J16: =SUM(J4:J15) -> 5 | K16: =SUM(K4:K15) -> 4 | L16: =SUM(L4:L15) -> 21 | M16: =SUM(M4:M15) -> 2 | N16: =SUM(N4:N15) -> 2 | O16: =SUM(O4:O15) -> 34 | P16: =H16+O16 -> 51
A18: Note: Per department rule, only the SALES (CLOSES) total counts toward the Commercial department's official weekly total (Commercial tab, row 37). FRONTS are tracked here separately for lead-generation performance and are not part of the department's sales total.

Sheet COM Winbacks
A1: Rep # | B1: Rep Name | C1: Monday | D1: Tuesday | E1: Wednesday | F1: Thursday | G1: Friday | H1: Nights | I1: Saturday | J1: Total COMP | K1: BAD TPV | L1: TOTAL WK | M1: Last Week | N1: Difference | O1: Program | P1: Manager
A2: IN HOUSE AGENTS
J3: =SUM(C3:I3) -> 0 | L3: =J3-K3 -> 0 | M3: 0 | N3: =J3-M3 -> 0 | O3: ELIGO | P3: CJ
J4: =SUM(C4:I4) -> 0 | L4: =J4-K4 -> 0 | M4: 0 | N4: =J4-M4 -> 0 | O4: ELIGO | P4: CJ
J5: =SUM(C5:I5) -> 0 | L5: =J5-K5 -> 0 | M5: 0 | N5: =J5-M5 -> 0 | O5: ELIGO | P5: CJ
J6: =SUM(C6:I6) -> 0 | L6: =J6-K6 -> 0 | M6: 0 | N6: =J6-M6 -> 0 | O6: ELIGO | P6: CJ
J7: =SUM(C7:I7) -> 0 | L7: =J7-K7 -> 0 | M7: 0 | N7: =J7-M7 -> 0 | O7: ELIGO | P7: CJ
J8: =SUM(C8:I8) -> 0 | L8: =J8-K8 -> 0 | M8: 0 | N8: =J8-M8 -> 0 | O8: ELIGO | P8: CJ
J9: =SUM(C9:I9) -> 0 | L9: =J9-K9 -> 0 | M9: 0 | N9: =J9-M9 -> 0 | O9: ELIGO | P9: CJ
J10: =SUM(C10:I10) -> 0 | L10: =J10-K10 -> 0 | M10: 0 | N10: =J10-M10 -> 0 | O10: ELIGO | P10: CJ
B11: Total | C11: =SUM(C3) -> 0 | D11: =SUM(D3) -> 0 | E11: =SUM(E3) -> 0 | F11: =SUM(F3) -> 0 | G11: =SUM(G3) -> 0 | H11: =SUM(H3) -> 0 | I11: =SUM(I3) -> 0 | J11: =SUM(J3:J10) -> 0 | K11: =SUM(K3) -> 0 | L11: =SUM(L3:L10) -> 0 | M11: =SUM(M3:M10) -> 0 | N11: =J11-M11 -> 0 | O11: ELIGO | P11: CJ
B12: Night Shift
A13: Rep # | B13: Rep Name | C13: Monday | D13: Tuesday | E13: Wednesday | F13: Thursday | G13: Friday | H13: Nights | I13: Saturday | J13: Total COMP | K13: BAD TPV | L13: TOTAL WK | M13: Last Week | N13: Difference | O13: Program | P13: Manager
J14: =SUM(C14:I14) -> 0 | L14: =J14-K14 -> 0 | M14: 0 | N14: =J14-M14 -> 0 | O14: ELIGO | P14: CJ
J15: =SUM(C15:I15) -> 0 | L15: =J15-K15 -> 0 | M15: 0 | N15: =J15-M15 -> 0 | O15: ELIGO | P15: CJ
J16: =SUM(C16:I16) -> 0 | L16: =J16-K16 -> 0 | M16: 0 | N16: =J16-M16 -> 0 | O16: ELIGO | P16: CJ
J17: =SUM(C17:I17) -> 0 | L17: =J17-K17 -> 0 | M17: 0 | N17: =J17-M17 -> 0 | O17: ELIGO | P17: CJ
J18: =SUM(C18:I18) -> 0 | L18: =J18-K18 -> 0 | M18: 0 | N18: =J18-M18 -> 0 | O18: ELIGO | P18: CJ
B19: Total | C19: =SUM(C14:C17) -> 0 | D19: =SUM(D14:D17) -> 0 | E19: =SUM(E14:E17) -> 0 | F19: =SUM(F14:F17) -> 0 | G19: =SUM(G14:G17) -> 0 | H19: =SUM(H14:H17) -> 0 | I19: =SUM(I14:I17) -> 0 | J19: =SUM(J14:J17) -> 0 | ... M19: =SUM(M14:M17) -> 0 | N19: =J19-M19 -> 0 | O19: ELIGO | P19: CJ
B20: TRAINING (in house)
A21: Rep # | B21: Rep Name | C21: Monday | D21: Tuesday | E21: Wednesday | F21: Thursday | G21: Friday | H21: Nights | I21: Saturday | J21: Total COMP | K21: BAD TPV | L21: TOTAL WK | M21: Last Week | N21: Difference | O21: Program | P21: Manager
J22: =SUM(C22:I22) -> 0 | L22: =J22-K22 -> 0 | M22: 0 | N22: =J22-M22 -> 0 | O22: ELIGO | P22: CJ
J23: =SUM(C23:I23) -> 0 | L23: =J23-K23 -> 0 | M23: 0 | N23: =J23-M23 -> 0 | O23: ELIGO | P23: CJ
J24: =SUM(C24:I24) -> 0 | L24: =J24-K24 -> 0 | M24: 0 | N24: =J24-M24 -> 0 | O24: ELIGO | P24: CJ
B25: Total | C25: =SUM(C22:C23) -> 0 | D25: =SUM(D22:D23) -> 0 | E25: =SUM(E22:E23) -> 0 | F25: =SUM(F22:F23) -> 0 | G25: =SUM(G22:G23) -> 0 | H25: =SUM(H22:H23) -> 0 | I25: =SUM(I22:I23) -> 0 | J25: =SUM(J22:J23) -> 0 | ... M25: =SUM(M22:M23) -> 0 | N25: =J25-M25 -> 0 | O25: ELIGO | P25: CJ
B26: Admin Staff
J27: =SUM(C27:I27) -> 0 | L27: =J27-K27 -> 0 | M27: 0 | N27: =J27-M27 -> 0 | O27: ELIGO | P27: CJ
J28: =SUM(C28:I28) -> 0 | L28: =J28-K28 -> 0 | M28: 0 | N28: =J28-M28 -> 0 | O28: ELIGO | P28: CJ
J29: =SUM(C29:I29) -> 0 | L29: =J29-K29 -> 0 | M29: 0 | N29: =J29-M29 -> 0 | O29: ELIGO | P29: CJ
J30: =SUM(C30:I30) -> 0 | L30: =J30-K30 -> 0 | M30: 0 | N30: =J30-M30 -> 0 | O30: ELIGO | P30: CJ
B31: Total | C31: =SUM(C11,C19,C25) -> 0 | D31: =SUM(D11,D19,D25) -> 0 | E31: =SUM(E11,E19,E25) -> 0 | F31: =SUM(F11,F19,F25) -> 0 | G31: =SUM(G11,G19,G25) -> 0 | H31: =SUM(H11,H19,H25) -> 0 | J31: =SUM(J11,J19,J25) -> 0 | K31: =SUM(K11,K19,K25) -> 0 | L31: =SUM(L11,L19,L25) -> 0 | M31: =SUM(M11,M19,M25) -> 0 | N31: =J31-M31 -> 0
B32: Last Week | C32: 0 | D32: 0 | E32: 0 | F32: 0 | G32: 0 | H32: 0 | J32: 0
B33: Difference | C33: =C31-C32 -> 0 | D33: =D31-D32 -> 0 | E33: =E31-E32 -> 0 | F33: =F31-F32 -> 0 | G33: =G31-G32 -> 0 | H33: =H31-H32 -> 0 | J33: =J31-J32 -> 0

Sheet Residential
A1: Rep # | B1: Rep Name | C1: Monday | D1: Tuesday | E1: Wednesday | F1: Thursday | G1: Friday | H1: Total COMP | I1: BAD TPV | J1: TOTAL WK | K1: Last Week | L1: Difference | M1: Program | N1: Manager
A2: IN HOUSE AGENTS
A3: 1290 | B3: Abigail Gambino (Commercial-Closer) | C3: {=IFERROR(_xlfn.XLOOKUP($A3,Commercial!$A:$A,Commercial!$F:$F,0,0),0)} -> 0 | D3: {=IFERROR(_xlfn.XLOOKUP($A3,Commercial!$A:$A,Commercial!$L:$L,0,0),0)} -> 0 | E3: {=IFERROR(_xlfn.XLOOKUP($A3,Commercial!$A:$A,Commercial!$R:$R,0,0),0)} -> 0 | F3: {=IFERROR(_xlfn.XLOOKUP($A3,Commercial!$A:$A,Commercial!$X:$X,0,0),0)} -> 0 | G3: {=IFERROR(_xlfn.XLOOKUP($A3,Commercial!$A:$A,Commercial!$AD:$AD,0,0),0)} -> 0 | H3: =SUM(C3:G3) -> 0 | J3: =H3-I3 -> 0 | K3: 0 | L3: =H3-K3 -> 0 | M3: ELIGO | N3: CJ
A4: 1301 | B4: Albert Williams (Commercial) | C4: {=IFERROR(_xlfn.XLOOKUP($A4,Commercial!$A:$A,Commercial!$F:$F,0,0),0)} -> 0 | D4: {=IFERROR(_xlfn.XLOOKUP($A4,Commercial!$A:$A,Commercial!$L:$L,0,0),0)} -> 0 | E4: {=IFERROR(_xlfn.XLOOKUP($A4,Commercial!$A:$A,Commercial!$R:$R,0,0),0)} -> 0 | F4: {=IFERROR(_xlfn.XLOOKUP($A4,Commercial!$A:$A,Commercial!$X:$X,0,0),0)} -> 0 | G4: {=IFERROR(_xlfn.XLOOKUP($A4,Commercial!$A:$A,Commercial!$AD:$AD,0,0),0)} -> 0 | H4: =SUM(C4:G4) -> 0 | J4: =H4-I4 -> 0 | K4: 0 | L4: =H4-K4 -> 0 | M4: ELIGO | N4: CJ
A5: 1288 | B5: Allen Alberts(Commercial-Closer) | C5: {=IFERROR(_xlfn.XLOOKUP($A5,Commercial!$A:$A,Commercial!$F:$F,0,0),0)} -> 0 | D5: {=IFERROR(_xlfn.XLOOKUP($A5,Commercial!$A:$A,Commercial!$L:$L,0,0),0)} -> 0 | E5: {=IFERROR(_xlfn.XLOOKUP($A5,Commercial!$A:$A,Commercial!$R:$R,0,0),0)} -> 0 | F5: {=IFERROR(_xlfn.XLOOKUP($A5,Commercial!$A:$A,Commercial!$X:$X,0,0),0)} -> 0 | G5: {=IFERROR(_xlfn.XLOOKUP($A5,Commercial!$A:$A,Commercial!$AD:$AD,0,0),0)} -> 0 | H5: =SUM(C5:G5) -> 0 | J5: =H5-I5 -> 0 | K5: 0 | L5: =H5-K5 -> 0 | M5: ELIGO | N5: CJ
A6: 1280 | B6: Ashlee Franks (Commercial) | C6: {=IFERROR(_xlfn.XLOOKUP($A6,Commercial!$A:$A,Commercial!$F:$F,0,0),0)} -> 0 | D6: {=IFERROR(_xlfn.XLOOKUP($A6,Commercial!$A:$A,Commercial!$L:$L,0,0),0)} -> 0 | E6: {=IFERROR(_xlfn.XLOOKUP($A6,Commercial!$A:$A,Commercial!$R:$R,0,0),0)} -> 0 | F6: {=IFERROR(_xlfn.XLOOKUP($A6,Commercial!$A:$A,Commercial!$X:$X,0,0),0)} -> 0 | G6: {=IFERROR(_xlfn.XLOOKUP($A6,Commercial!$A:$A,Commercial!$AD:$AD,0,0),0)} -> 0 | H6: =SUM(C6:G6) -> 0 | J6: =H6-I6 -> 0 | K6: 0 | L6: =H6-K6 -> 0 | M6: ELIGO | N6: CJ
A7: 1294 | B7: Brandy Paton (Commercial) | C7: {=IFERROR(_xlfn.XLOOKUP($A7,Commercial!$A:$A,Commercial!$F:$F,0,0),0)} -> 0 | D7: {=IFERROR(_xlfn.XLOOKUP($A7,Commercial!$A:$A,Commercial!$L:$L,0,0),0)} -> 0 | E7: {=IFERROR(_xlfn.XLOOKUP($A7,Commercial!$A:$A,Commercial!$R:$R,0,0),0)} -> 0 | F7: {=IFERROR(_xlfn.XLOOKUP($A7,Commercial!$A:$A,Commercial!$X:$X,0,0),0)} -> 0 | G7: {=IFERROR(_xlfn.XLOOKUP($A7,Commercial!$A:$A,Commercial!$AD:$AD,0,0),0)} -> 0 | H7: =SUM(C7:G7) -> 0 | J7: =H7-I7 -> 0 | K7: 0 | L7: =H7-K7 -> 0 | M7: ELIGO | N7: CJ
A8: 1292 | B8: Jakarta Hunter (Commercial) | C8: {=IFERROR(_xlfn.XLOOKUP($A8,Commercial!$A:$A,Commercial!$F:$F,0,0),0)} -> 0 | D8: {=IFERROR(_xlfn.XLOOKUP($A8,Commercial!$A:$A,Commercial!$L:$L,0,0),0)} -> 0 | E8: {=IFERROR(_xlfn.XLOOKUP($A8,Commercial!$A:$A,Commercial!$R:$R,0,0),0)} -> 0 | F8: {=IFERROR(_xlfn.XLOOKUP($A8,Commercial!$A:$A,Commercial!$X:$X,0,0),0)} -> 0 | G8: {=IFERROR(_xlfn.XLOOKUP($A8,Commercial!$A:$A,Commercial!$AD:$AD,0,0),0)} -> 0 | H8: =SUM(C8:G8) -> 0 | J8: =H8-I8 -> 0 | K8: 0 | L8: =H8-K8 -> 0 | M8: ELIGO | N8: CJ
A9: 1175 | B9: Kenticka Tate (Remote)(Commercial) | C9: {=IFERROR(_xlfn.XLOOKUP($A9,Commercial!$A:$A,Commercial!$F:$F,0,0),0)} -> 0 | D9: {=IFERROR(_xlfn.XLOOKUP($A9,Commercial!$A:$A,Commercial!$L:$L,0,0),0)} -> 0 | E9: {=IFERROR(_xlfn.XLOOKUP($A9,Commercial!$A:$A,Commercial!$R:$R,0,0),0)} -> 0 | F9: {=IFERROR(_xlfn.XLOOKUP($A9,Commercial!$A:$A,Commercial!$X:$X,0,0),0)} -> 0 | G9: {=IFERROR(_xlfn.XLOOKUP($A9,Commercial!$A:$A,Commercial!$AD:$AD,0,0),0)} -> 0 | H9: =SUM(C9:G9) -> 0 | J9: =H9-I9 -> 0 | K9: 0 | L9: =H9-K9 -> 0 | M9: ELIGO | N9: CJ
A10: 1295 | B10: Luis Buitrago (Commercial) | C10: {=IFERROR(_xlfn.XLOOKUP($A10,Commercial!$A:$A,Commercial!$F:$F,0,0),0)} -> 0 | D10: {=IFERROR(_xlfn.XLOOKUP($A10,Commercial!$A:$A,Commercial!$L:$L,0,0),0)} -> 0 | E10: {=IFERROR(_xlfn.XLOOKUP($A10,Commercial!$A:$A,Commercial!$R:$R,0,0),0)} -> 0 | F10: {=IFERROR(_xlfn.XLOOKUP($A10,Commercial!$A:$A,Commercial!$X:$X,0,0),0)} -> 0 | G10: {=IFERROR(_xlfn.XLOOKUP($A10,Commercial!$A:$A,Commercial!$AD:$AD,0,0),0)} -> 0 | H10: =SUM(C10:G10) -> 0 | J10: =H10-I10 -> 0 | K10: 0 | L10: =H10-K10 -> 0 | M10: ELIGO | N10: CJ
A11: 1300 | B11: Neil Singhal (Commercial) | C11: {=IFERROR(_xlfn.XLOOKUP($A11,Commercial!$A:$A,Commercial!$F:$F,0,0),0)} -> 0 | D11: {=IFERROR(_xlfn.XLOOKUP($A11,Commercial!$A:$A,Commercial!$L:$L,0,0),0)} -> 0 | E11: {=IFERROR(_xlfn.XLOOKUP($A11,Commercial!$A:$A,Commercial!$R:$R,0,0),0)} -> 0 | F11: {=IFERROR(_xlfn.XLOOKUP($A11,Commercial!$A:$A,Commercial!$X:$X,0,0),0)} -> 0 | G11: {=IFERROR(_xlfn.XLOOKUP($A11,Commercial!$A:$A,Commercial!$AD:$AD,0,0),0)} -> 0 | H11: =SUM(C11:G11) -> 0 | J11: =H11-I11 -> 0 | K11: 0 | L11: =H11-K11 -> 0 | M11: ELIGO | N11: CJ
A12: 1291 | B12: Raven Mitchell (Commercial) | C12: {=IFERROR(_xlfn.XLOOKUP($A12,Commercial!$A:$A,Commercial!$F:$F,0,0),0)} -> 0 | D12: {=IFERROR(_xlfn.XLOOKUP($A12,Commercial!$A:$A,Commercial!$L:$L,0,0),0)} -> 0 | E12: {=IFERROR(_xlfn.XLOOKUP($A12,Commercial!$A:$A,Commercial!$R:$R,0,0),0)} -> 0 | F12: {=IFERROR(_xlfn.XLOOKUP($A12,Commercial!$A:$A,Commercial!$X:$X,0,0),0)} -> 0 | G12: {=IFERROR(_xlfn.XLOOKUP($A12,Commercial!$A:$A,Commercial!$AD:$AD,0,0),0)} -> 0 | H12: =SUM(C12:G12) -> 0 | J12: =H12-I12 -> 0 | K12: 0 | L12: =H12-K12 -> 0 | M12: ELIGO | N12: CJ
A13: 1220 | B13: Sara Milanese (Commercial) | C13: {=IFERROR(_xlfn.XLOOKUP($A13,Commercial!$A:$A,Commercial!$F:$F,0,0),0)} -> 0 | D13: {=IFERROR(_xlfn.XLOOKUP($A13,Commercial!$A:$A,Commercial!$L:$L,0,0),0)} -> 0 | E13: {=IFERROR(_xlfn.XLOOKUP($A13,Commercial!$A:$A,Commercial!$R:$R,0,0),0)} -> 0 | F13: {=IFERROR(_xlfn.XLOOKUP($A13,Commercial!$A:$A,Commercial!$X:$X,0,0),0)} -> 0 | G13: {=IFERROR(_xlfn.XLOOKUP($A13,Commercial!$A:$A,Commercial!$AD:$AD,0,0),0)} -> 0 | H13: =SUM(C13:G13) -> 0 | J13: =H13-I13 -> 0 | K13: 0 | L13: =H13-K13 -> 0 | M13: ELIGO | N13: CJ
A14: 1298 | B14: Shelby Lewis (Commercial) | C14: {=IFERROR(_xlfn.XLOOKUP($A14,Commercial!$A:$A,Commercial!$F:$F,0,0),0)} -> 0 | D14: {=IFERROR(_xlfn.XLOOKUP($A14,Commercial!$A:$A,Commercial!$L:$L,0,0),0)} -> 0 | E14: {=IFERROR(_xlfn.XLOOKUP($A14,Commercial!$A:$A,Commercial!$R:$R,0,0),0)} -> 0 | F14: {=IFERROR(_xlfn.XLOOKUP($A14,Commercial!$A:$A,Commercial!$X:$X,0,0),0)} -> 0 | G14: {=IFERROR(_xlfn.XLOOKUP($A14,Commercial!$A:$A,Commercial!$AD:$AD,0,0),0)} -> 0 | H14: =SUM(C14:G14) -> 0 | J14: =H14-I14 -> 0 | K14: 0 | L14: =H14-K14 -> 0 | M14: ELIGO | N14: CJ
H15: =SUM(C15:G15) -> 0 | J15: =H15-I15 -> 0 | K15: 0 | L15: =H15-K15 -> 0 | M15: ELIGO | N15: CJ
H16: =SUM(C16:G16) -> 0 | J16: =H16-I16 -> 0 | K16: 0 | L16: =H16-K16 -> 0 | M16: ELIGO | N16: CJ
B17: Total | C17: =SUM(C3:C16) -> 0 | D17: =SUM(D3:D16) -> 0 | E17: =SUM(E3:E16) -> 0 | F17: =SUM(F3:F16) -> 0 | G17: =SUM(G3:G16) -> 0 | H17: =SUM(C17:G17) -> 0 | K17: =SUM(K3:K16) -> 0 | M17: ELIGO | N17: CJ
B18: Night Shift
A19: Rep # | B19: Rep Name | C19: Monday | D19: Tuesday | E19: Wednesday | F19: Thursday | G19: Friday | H19: Total COMP | I19: BAD TPV | J19: TOTAL WK | K19: Last Week | L19: Difference | M19: Program | N19: Manager
H20: =SUM(C20:G20) -> 0 | J20: =H20-I20 -> 0 | K20: 0 | L20: =H20-K20 -> 0 | M20: ELIGO | N20: CJ
H21: =SUM(C21:G21) -> 0 | J21: =H21-I21 -> 0 | K21: 0 | L21: =H21-K21 -> 0 | M21: ELIGO | N21: CJ
H22: =SUM(C22:G22) -> 0 | J22: =H22-I22 -> 0 | K22: 0 | L22: =H22-K22 -> 0 | M22: ELIGO | N22: CJ
H23: =SUM(C23:G23) -> 0 | J23: =H23-I23 -> 0 | K23: 0 | L23: =H23-K23 -> 0 | M23: ELIGO | N23: CJ
H24: =SUM(C24:G24) -> 0 | J24: =H24-I24 -> 0 | K24: 0 | L24: =H24-K24 -> 0 | M24: ELIGO | N24: CJ
H25: =SUM(C25:G25) -> 0 | J25: =H25-I25 -> 0 | K25: 0 | L25: =H25-K25 -> 0 | M25: ELIGO | N25: CJ
H26: =SUM(C26:G26) -> 0 | J26: =H26-I26 -> 0 | K26: 0 | L26: =H26-K26 -> 0 | M26: ELIGO | N26: CJ
H27: =SUM(C27:G27) -> 0 | J27: =H27-I27 -> 0 | K27: 0 | L27: =H27-K27 -> 0 | M27: ELIGO | N27: CJ
H28: =SUM(C28:G28) -> 0 | J28: =H28-I28 -> 0 | K28: 0 | L28: =H28-K28 -> 0 | M28: ELIGO | N28: CJ
H29: =SUM(C29:G29) -> 0 | J29: =H29-I29 -> 0 | K29: 0 | L29: =H29-K29 -> 0 | M29: ELIGO | N29: CJ
B30: Total | C30: =SUM(C20:C23) -> 0 | D30: =SUM(D20:D23) -> 0 | E30: =SUM(E20:E23) -> 0 | F30: =SUM(F20:F23) -> 0 | G30: =SUM(G20:G23) -> 0 | H30: =SUM(H20:H29) -> 0 | I30: =SUM(I20:I23) -> 0 | J30: =SUM(J20:J29) -> 0 | K30: =SUM(K20) -> 0 | L30: =H30-K30 -> 0 | M30: ELIGO | N30: CJ
B31: TRAINING (in house)
A32: Rep # | B32: Rep Name | C32: Monday | D32: Tuesday | E32: Wednesday | F32: Thursday | G32: Friday | H32: Total COMP | I32: BAD TPV | J32: TOTAL WK | K32: Last Week | L32: Difference | M32: Program | N32: Manager
H33: =SUM(C33:G33) -> 0 | J33: =H33-I33 -> 0 | K33: 0 | L33: =H33-K33 -> 0 | M33: ELIGO | N33: CJ
H34: =SUM(C34:G34) -> 0 | J34: =H34-I34 -> 0 | K34: 0 | L34: =H34-K34 -> 0 | M34: ELIGO | N34: CJ
H35: =SUM(C35:G35) -> 0 | J35: =H35-I35 -> 0 | K35: 0 | L35: =H35-K35 -> 0 | M35: ELIGO | N35: CJ
H36: =SUM(C36:G36) -> 0 | J36: =H36-I36 -> 0 | K36: 0 | L36: =H36-K36 -> 0 | M36: ELIGO | N36: CJ
B37: Admin Staff
H38: =SUM(C38:G38) -> 0 | J38: =H38-I38 -> 0 | K38: 0 | L38: =H38-K38 -> 0 | M38: ELIGO | N38: CJ
H39: =SUM(C39:G39) -> 0 | J39: =H39-I39 -> 0 | K39: 0 | L39: =H39-K39 -> 0 | M39: ELIGO | N39: CJ
H40: =SUM(C40:G40) -> 0 | J40: =H40-I40 -> 0 | K40: 0 | L40: =H40-K40 -> 0 | M40: ELIGO | N40: CJ
...

Sheet Dashboard
A1: Rep # | B1: Rep Name | C1: COM Winbacks | H1: Residential | M1: Commercial | R1: DAILY TOTALS | W1: Grand Total
B2: FRONTERS | C2: Mon | D2: Tue | E2: Wed | F2: Thu | G2: Fri | H2: Mon | I2: Tue | J2: Wed | K2: Thu | L2: Fri | M2: Mon | N2: Tue | O2: Wed | P2: Thu | Q2: Fri | R2: Mon | S2: Tue | T2: Wed | U2: Thu | V2: Fri
A3: =Commercial!A3 -> 1291 | B3: {=IFERROR(INDEX(Commercial!B:B,MATCH(A3,Commercial!A:A,0)),"")} -> Raven Mitchell (Commercial) | C3: =IFERROR(SUMIF('COM Winbacks'!$A:$A,$A3,'COM Winbacks'!C:C),0) -> 0 | D3: =IFERROR(SUMIF('COM Winbacks'!$A:$A,$A3,'COM Winbacks'!D:D),0) -> 0 | E3: =IFERROR(SUMIF('COM Winbacks'!$A:$A,$A3,'COM Winbacks'!E:E),0) -> 0 | F3: =IFERROR(SUMIF('COM Winbacks'!$A:$A,$A3,'COM Winbacks'!F:F),0) -> 0 | G3: =IFERROR(SUMIF('COM Winbacks'!$A:$A,$A3,'COM Winbacks'!G:G),0) -> 0 | H3: =IFERROR(SUMIF(Residential!$A:$A,$A3,Residential!C:C),0) -> 0 | I3: =IFERROR(SUMIF(Residential!$A:$A,$A3,Residential!D:D),0) -> 0 | J3: =IFERROR(SUMIF(Residential!$A:$A,$A3,Residential!E:E),0) -> 0 | K3: =IFERROR(SUMIF(Residential!$A:$A,$A3,Residential!F:F),0) -> 0 | L3: =IFERROR(SUMIF(Residential!$A:$A,$A3,Residential!G:G),0) -> 0 | M3: =IFERROR(SUMIF(Commercial!$A$3:$A$11,$A3,Commercial!Q$3:Q$11),0) -> 3 | N3: =IFERROR(SUMIF(Commercial!$A$3:$A$11,$A3,Commercial!V$3:V$11),0) -> 2 | O3: =IFERROR(SUMIF(Commercial!$A$3:$A$11,$A3,Commercial!W$3:W$11),0) -> 0 | P3: =IFERROR(SUMIF(Commercial!$A$3:$A$11,$A3,Commercial!AB$3:AB$11),0) -> 1 | Q3: =IFERROR(SUMIF(Commercial!$A$3:$A$11,$A3,Commercial!AC$3:AC$11),0) -> 0 | R3: =C3+H3+M3 -> 3 | S3: =D3+I3+N3 -> 2 | T3: =E3+J3+O3 -> 0 | U3: =F3+K3+P3 -> 1 | V3: =G3+L3+Q3 -> 0 | W3: =SUM(R3:V3) -> 6
A4: =Commercial!A4 -> 1292 | B4: {=IFERROR(INDEX(Commercial!B:B,MATCH(A4,Commercial!A:A,0)),"")} -> Jakarta Hunter (Commercial) | C4: =IFERROR(SUMIF('COM Winbacks'!$A:$A,$A4,'COM Winbacks'!C:C),0) -> 0 | D4: =IFERROR(SUMIF('COM Winbacks'!$A:$A,$A4,'COM Winbacks'!D:D),0) -> 0 | E4: =IFERROR(SUMIF('COM Winbacks'!$A:$A,$A4,'COM Winbacks'!E:E),0) -> 0 | F4: =IFERROR(SUMIF('COM Winbacks'!$A:$A,$A4,'COM Winbacks'!F:F),0) -> 0 | G4: =IFERROR(SUMIF('COM Winbacks'!$A:$A,$A4,'COM Winbacks'!G:G),0) -> 0 | H4: =IFERROR(SUMIF(Residential!$A:$A,$A4,Residential!C:C),0) -> 0 | I4: =IFERROR(SUMIF(Residential!$A:$A,$A4,Residential!D:D),0) -> 0 | J4: =IFERROR(SUMIF(Residential!$A:$A,$A4,Residential!E:E),0) -> 0 | K4: =IFERROR(SUMIF(Residential!$A:$A,$A4,Residential!F:F),0) -> 0 | L4: =IFERROR(SUMIF(Residential!$A:$A,$A4,Residential!G:G),0) -> 0 | M4: =IFERROR(SUMIF(Commercial!$A$3:$A$11,$A4,Commercial!Q$3:Q$11),0) -> 0 | N4: =IFERROR(SUMIF(Commercial!$A$3:$A$11,$A4,Commercial!V$3:V$11),0) -> 0 | O4: =IFERROR(SUMIF(Commercial!$A$3:$A$11,$A4,Commercial!W$3:W$11),0) -> 0 | P4: =IFERROR(SUMIF(Commercial!$A$3:$A$11,$A4,Commercial!AB$3:AB$11),0) -> 0 | Q4: =IFERROR(SUMIF(Commercial!$A$3:$A$11,$A4,Commercial!AC$3:AC$11),0) -> 0 | R4: =C4+H4+M4 -> 0 | S4: =D4+I4+N4 -> 0 | T4: =E4+J4+O4 -> 0 | U4: =F4+K4+P4 -> 0 | V4: =G4+L4+Q4 -> 0 | W4: =SUM(R4:V4) -> 0
A5: =Commercial!A5 -> 1295 | B5: {=IFERROR(INDEX(Commercial!B:B,MATCH(A5,Commercial!A:A,0)),"")} -> Luis Buitrago (Commercial) | C5: =IFERROR(SUMIF('COM Winbacks'!$A:$A,$A5,'COM Winbacks'!C:C),0) -> 0 | D5: =IFERROR(SUMIF('COM Winbacks'!$A:$A,$A5,'COM Winbacks'!D:D),0) -> 0 | E5: =IFERROR(SUMIF('COM Winbacks'!$A:$A,$A5,'COM Winbacks'!E:E),0) -> 0 | F5: =IFERROR(SUMIF('COM Winbacks'!$A:$A,$A5,'COM Winbacks'!F:F),0) -> 0 | G5: =IFERROR(SUMIF('COM Winbacks'!$A:$A,$A5,'COM Winbacks'!G:G),0) -> 0 | H5: =IFERROR(SUMIF(Residential!$A:$A,$A5,Residential!C:C),0) -> 0 | I5: =IFERROR(SUMIF(Residential!$A:$A,$A5,Residential!D:D),0) -> 0 | J5: =IFERROR(SUMIF(Residential!$A:$A,$A5,Residential!E:E),0) -> 0 | K5: =IFERROR(SUMIF(Residential!$A:$A,$A5,Residential!F:F),0) -> 0 | L5: =IFERROR(SUMIF(Residential!$A:$A,$A5,Residential!G:G),0) -> 0 | M5: =IFERROR(SUMIF(Commercial!$A$3:$A$11,$A5,Commercial!Q$3:Q$11),0) -> 0 | N5: =IFERROR(SUMIF(Commercial!$A$3:$A$11,$A5,Commercial!V$3:V$11),0) -> 0 | O5: =IFERROR(SUMIF(Commercial!$A$3:$A$11,$A5,Commercial!W$3:W$11),0) -> 0 | P5: =IFERROR(SUMIF(Commercial!$A$3:$A$11,$A5,Commercial!AB$3:AB$11),0) -> 0 | Q5: =IFERROR(SUMIF(Commercial!$A$3:$A$11,$A5,Commercial!AC$3:AC$11),0) -> 0 | R5: =C5+H5+M5 -> 0 | S5: =D5+I5+N5 -> 0 | T5: =E5+J5+O5 -> 0 | U5: =F5+K5+P5 -> 0 | V5: =G5+L5+Q5 -> 0 | W5: =SUM(R5:V5) -> 0
A6: =Commercial!#REF! -> #REF! | B6: {=IFERROR(INDEX(Commercial!B:B,MATCH(A6,Commercial!A:A,0)),"")} | C6: =IFERROR(SUMIF('COM Winbacks'!$A:$A,$A6,'COM Winbacks'!C:C),0) -> 0 | D6: =IFERROR(SUMIF('COM Winbacks'!$A:$A,$A6,'COM Winbacks'!D:D),0) -> 0 | E6: =IFERROR(SUMIF('COM Winbacks'!$A:$A,$A6,'COM Winbacks'!E:E),0) -> 0 | F6: =IFERROR(SUMIF('COM Winbacks'!$A:$A,$A6,'COM Winbacks'!F:F),0) -> 0 | G6: =IFERROR(SUMIF('COM Winbacks'!$A:$A,$A6,'COM Winbacks'!G:G),0) -> 0 | H6: =IFERROR(SUMIF(Residential!$A:$A,$A6,Residential!C:C),0) -> 0 | I6: =IFERROR(SUMIF(Residential!$A:$A,$A6,Residential!D:D),0) -> 0 | J6: =IFERROR(SUMIF(Residential!$A:$A,$A6,Residential!E:E),0) -> 0 | K6: =IFERROR(SUMIF(Residential!$A:$A,$A6,Residential!F:F),0) -> 0 | L6: =IFERROR(SUMIF(Residential!$A:$A,$A6,Residential!G:G),0) -> 0 | M6: =IFERROR(SUMIF(Commercial!$A$3:$A$11,$A6,Commercial!Q$3:Q$11),0) -> 0 | N6: =IFERROR(SUMIF(Commercial!$A$3:$A$11,$A6,Commercial!V$3:V$11),0) -> 0 | O6: =IFERROR(SUMIF(Commercial!$A$3:$A$11,$A6,Commercial!W$3:W$11),0) -> 0 | P6: =IFERROR(SUMIF(Commercial!$A$3:$A$11,$A6,Commercial!AB$3:AB$11),0) -> 0 | Q6: =IFERROR(SUMIF(Commercial!$A$3:$A$11,$A6,Commercial!AC$3:AC$11),0) -> 0 | R6: =C6+H6+M6 -> 0 | S6: =D6+I6+N6 -> 0 | T6: =E6+J6+O6 -> 0 | U6: =F6+K6+P6 -> 0 | V6: =G6+L6+Q6 -> 0 | W6: =SUM(R6:V6) -> 0
A7: =Commercial!A6 -> 1288 | B7: {=IFERROR(INDEX(Commercial!B:B,MATCH(A7,Commercial!A:A,0)),"")} -> Allen Alberts(Commercial-Closer) | C7: =IFERROR(SUMIF('COM Winbacks'!$A:$A,$A7,'COM Winbacks'!C:C),0) -> 0 | D7: =IFERROR(SUMIF('COM Winbacks'!$A:$A,$A7,'COM Winbacks'!D:D),0) -> 0 | E7: =IFERROR(SUMIF('COM Winbacks'!$A:$A,$A7,'COM Winbacks'!E:E),0) -> 0 | F7: =IFERROR(SUMIF('COM Winbacks'!$A:$A,$A7,'COM Winbacks'!F:F),0) -> 0 | G7: =IFERROR(SUMIF('COM Winbacks'!$A:$A,$A7,'COM Winbacks'!G:G),0) -> 0 | H7: =IFERROR(SUMIF(Residential!$A:$A,$A7,Residential!C:C),0) -> 0 | I7: =IFERROR(SUMIF(Residential!$A:$A,$A7,Residential!D:D),0) -> 0 | J7: =IFERROR(SUMIF(Residential!$A:$A,$A7,Residential!E:E),0) -> 0 | K7: =IFERROR(SUMIF(Residential!$A:$A,$A7,Residential!F:F),0) -> 0 | L7: =IFERROR(SUMIF(Residential!$A:$A,$A7,Residential!G:G),0) -> 0 | M7: =IFERROR(SUMIF(Commercial!$A$3:$A$11,$A7,Commercial!Q$3:Q$11),0) -> 0 | N7: =IFERROR(SUMIF(Commercial!$A$3:$A$11,$A7,Commercial!V$3:V$11),0) -> 0 | O7: =IFERROR(SUMIF(Commercial!$A$3:$A$11,$A7,Commercial!W$3:W$11),0) -> 0 | P7: =IFERROR(SUMIF(Commercial!$A$3:$A$11,$A7,Commercial!AB$3:AB$11),0) -> 0 | Q7: =IFERROR(SUMIF(Commercial!$A$3:$A$11,$A7,Commercial!AC$3:AC$11),0) -> 0 | R7: =C7+H7+M7 -> 0 | S7: =D7+I7+N7 -> 0 | T7: =E7+J7+O7 -> 0 | U7: =F7+K7+P7 -> 0 | V7: =G7+L7+Q7 -> 0 | W7: =SUM(R7:V7) -> 0
A8: =Commercial!A7 -> 1175 | B8: {=IFERROR(INDEX(Commercial!B:B,MATCH(A8,Commercial!A:A,0)),"")} -> Kenticka Tate (Remote)(Commercial) | C8: =IFERROR(SUMIF('COM Winbacks'!$A:$A,$A8,'COM Winbacks'!C:C),0) -> 0 | D8: =IFERROR(SUMIF('COM Winbacks'!$A:$A,$A8,'COM Winbacks'!D:D),0) -> 0 | E8: =IFERROR(SUMIF('COM Winbacks'!$A:$A,$A8,'COM Winbacks'!E:E),0) -> 0 | F8: =IFERROR(SUMIF('COM Winbacks'!$A:$A,$A8,'COM Winbacks'!F:F),0) -> 0 | G8: =IFERROR(SUMIF('COM Winbacks'!$A:$A,$A8,'COM Winbacks'!G:G),0) -> 0 | H8: =IFERROR(SUMIF(Residential!$A:$A,$A8,Residential!C:C),0) -> 0 | I8: =IFERROR(SUMIF(Residential!$A:$A,$A8,Residential!D:D),0) -> 0 | J8: =IFERROR(SUMIF(Residential!$A:$A,$A8,Residential!E:E),0) -> 0 | K8: =IFERROR(SUMIF(Residential!$A:$A,$A8,Residential!F:F),0) -> 0 | L8: =IFERROR(SUMIF(Residential!$A:$A,$A8,Residential!G:G),0) -> 0 | M8: =IFERROR(SUMIF(Commercial!$A$3:$A$11,$A8,Commercial!Q$3:Q$11),0) -> 0 | N8: =IFERROR(SUMIF(Commercial!$A$3:$A$11,$A8,Commercial!V$3:V$11),0) -> 1 | O8: =IFERROR(SUMIF(Commercial!$A$3:$A$11,$A8,Commercial!W$3:W$11),0) -> 1 | P8: =IFERROR(SUMIF(Commercial!$A$3:$A$11,$A8,Commercial!AB$3:AB$11),0) -> 2 | Q8: =IFERROR(SUMIF(Commercial!$A$3:$A$11,$A8,Commercial!AC$3:AC$11),0) -> 1 | R8: =C8+H8+M8 -> 0 | S8: =D8+I8+N8 -> 1 | T8: =E8+J8+O8 -> 1 | U8: =F8+K8+P8 -> 2 | V8: =G8+L8+Q8 -> 1 | W8: =SUM(R8:V8) -> 5
A9: =Commercial!A8 -> 1294 | B9: {=IFERROR(INDEX(Commercial!B:B,MATCH(A9,Commercial!A:A,0)),"")} -> Brandy Paton (Commercial) | C9: =IFERROR(SUMIF('COM Winbacks'!$A:$A,$A9,'COM Winbacks'!C:C),0) -> 0 | D9: =IFERROR(SUMIF('COM Winbacks'!$A:$A,$A9,'COM Winbacks'!D:D),0) -> 0 | E9: =IFERROR(SUMIF('COM Winbacks'!$A:$A,$A9,'COM Winbacks'!E:E),0) -> 0 | F9: =IFERROR(SUMIF('COM Winbacks'!$A:$A,$A9,'COM Winbacks'!F:F),0) -> 0 | G9: =IFERROR(SUMIF('COM Winbacks'!$A:$A,$A9,'COM Winbacks'!G:G),0) -> 0 | H9: =IFERROR(SUMIF(Residential!$A:$A,$A9,Residential!C:C),0) -> 0 | I9: =IFERROR(SUMIF(Residential!$A:$A,$A9,Residential!D:D),0) -> 0 | J9: =IFERROR(SUMIF(Residential!$A:$A,$A9,Residential!E:E),0) -> 0 | K9: =IFERROR(SUMIF(Residential!$A:$A,$A9,Residential!F:F),0) -> 0 | L9: =IFERROR(SUMIF(Residential!$A:$A,$A9,Residential!G:G),0) -> 0 | M9: =IFERROR(SUMIF(Commercial!$A$3:$A$11,$A9,Commercial!Q$3:Q$11),0) -> 0 | N9: =IFERROR(SUMIF(Commercial!$A$3:$A$11,$A9,Commercial!V$3:V$11),0) -> 0 | O9: =IFERROR(SUMIF(Commercial!$A$3:$A$11,$A9,Commercial!W$3:W$11),0) -> 0 | P9: =IFERROR(SUMIF(Commercial!$A$3:$A$11,$A9,Commercial!AB$3:AB$11),0) -> 0 | Q9: =IFERROR(SUMIF(Commercial!$A$3:$A$11,$A9,Commercial!AC$3:AC$11),0) -> 0 | R9: =C9+H9+M9 -> 0 | S9: =D9+I9+N9 -> 0 | T9: =E9+J9+O9 -> 0 | U9: =F9+K9+P9 -> 0 | V9: =G9+L9+Q9 -> 0 | W9: =SUM(R9:V9) -> 0
A10: =Commercial!A9 -> 1280 | B10: {=IFERROR(INDEX(Commercial!B:B,MATCH(A10,Commercial!A:A,0)),"")} -> Ashlee Franks (Commercial) | C10: =IFERROR(SUMIF('COM Winbacks'!$A:$A,$A10,'COM Winbacks'!C:C),0) -> 0 | D10: =IFERROR(SUMIF('COM Winbacks'!$A:$A,$A10,'COM Winbacks'!D:D),0) -> 0 | E10: =IFERROR(SUMIF('COM Winbacks'!$A:$A,$A10,'COM Winbacks'!E:E),0) -> 0 | F10: =IFERROR(SUMIF('COM Winbacks'!$A:$A,$A10,'COM Winbacks'!F:F),0) -> 0 | G10: =IFERROR(SUMIF('COM Winbacks'!$A:$A,$A10,'COM Winbacks'!G:G),0) -> 0 | H10: =IFERROR(SUMIF(Residential!$A:$A,$A10,Residential!C:C),0) -> 0 | I10: =IFERROR(SUMIF(Residential!$A:$A,$A10,Residential!D:D),0) -> 0 | J10: =IFERROR(SUMIF(Residential!$A:$A,$A10,Residential!E:E),0) -> 0 | K10: =IFERROR(SUMIF(Residential!$A:$A,$A10,Residential!F:F),0) -> 0 | L10: =IFERROR(SUMIF(Residential!$A:$A,$A10,Residential!G:G),0) -> 0 | M10: =IFERROR(SUMIF(Commercial!$A$3:$A$11,$A10,Commercial!Q$3:Q$11),0) -> 4 | N10: =IFERROR(SUMIF(Commercial!$A$3:$A$11,$A10,Commercial!V$3:V$11),0) -> 0 | O10: =IFERROR(SUMIF(Commercial!$A$3:$A$11,$A10,Commercial!W$3:W$11),0) -> 0 | P10: =IFERROR(SUMIF(Commercial!$A$3:$A$11,$A10,Commercial!AB$3:AB$11),0) -> 0 | Q10: =IFERROR(SUMIF(Commercial!$A$3:$A$11,$A10,Commercial!AC$3:AC$11),0) -> 1 | R10: =C10+H10+M10 -> 4 | S10: =D10+I10+N10 -> 0 | T10: =E10+J10+O10 -> 0 | U10: =F10+K10+P10 -> 0 | V10: =G10+L10+Q10 -> 1 | W10: =SUM(R10:V10) -> 5
A11: =Commercial!A10 -> 1298 | B11: {=IFERROR(INDEX(Commercial!B:B,MATCH(A11,Commercial!A:A,0)),"")} -> Shelby Lewis (Commercial) | C11: =IFERROR(SUMIF('COM Winbacks'!$A:$A,$A11,'COM Winbacks'!C:C),0) -> 0 | D11: =IFERROR(SUMIF('COM Winbacks'!$A:$A,$A11,'COM Winbacks'!D:D),0) -> 0 | E11: =IFERROR(SUMIF('COM Winbacks'!$A:$A,$A11,'COM Winbacks'!E:E),0) -> 0 | F11: =IFERROR(SUMIF('COM Winbacks'!$A:$A,$A11,'COM Winbacks'!F:F),0) -> 0 | G11: =IFERROR(SUMIF('COM Winbacks'!$A:$A,$A11,'COM Winbacks'!G:G),0) -> 0 | H11: =IFERROR(SUMIF(Residential!$A:$A,$A11,Residential!C:C),0) -> 0 | I11: =IFERROR(SUMIF(Residential!$A:$A,$A11,Residential!D:D),0) -> 0 | J11: =IFERROR(SUMIF(Residential!$A:$A,$A11,Residential!E:E),0) -> 0 | K11: =IFERROR(SUMIF(Residential!$A:$A,$A11,Residential!F:F),0) -> 0 | L11: =IFERROR(SUMIF(Residential!$A:$A,$A11,Residential!G:G),0) -> 0 | M11: =IFERROR(SUMIF(Commercial!$A$3:$A$11,$A11,Commercial!Q$3:Q$11),0) -> 0 | N11: =IFERROR(SUMIF(Commercial!$A$3:$A$11,$A11,Commercial!V$3:V$11),0) -> 1 | O11: =IFERROR(SUMIF(Commercial!$A$3:$A$11,$A11,Commercial!W$3:W$11),0) -> 1 | P11: =IFERROR(SUMIF(Commercial!$A$3:$A$11,$A11,Commercial!AB$3:AB$11),0) -> 1 | Q11: =IFERROR(SUMIF(Commercial!$A$3:$A$11,$A11,Commercial!AC$3:AC$11),0) -> 0 | R11: =C11+H11+M11 -> 0 | S11: =D11+I11+N11 -> 1 | T11: =E11+J11+O11 -> 1 | U11: =F11+K11+P11 -> 1 | V11: =G11+L11+Q11 -> 0 | W11: =SUM(R11:V11) -> 3
A12: =Commercial!#REF! -> #REF! | B12: {=IFERROR(INDEX(Commercial!B:B,MATCH(A12,Commercial!A:A,0)),"")} | C12: =IFERROR(SUMIF('COM Winbacks'!$A:$A,$A12,'COM Winbacks'!C:C),0) -> 0 | D12: =IFERROR(SUMIF('COM Winbacks'!$A:$A,$A12,'COM Winbacks'!D:D),0) -> 0 | E12: =IFERROR(SUMIF('COM Winbacks'!$A:$A,$A12,'COM Winbacks'!E:E),0) -> 0 | F12: =IFERROR(SUMIF('COM Winbacks'!$A:$A,$A12,'COM Winbacks'!F:F),0) -> 0 | G12: =IFERROR(SUMIF('COM Winbacks'!$A:$A,$A12,'COM Winbacks'!G:G),0) -> 0 | H12: =IFERROR(SUMIF(Residential!$A:$A,$A12,Residential!C:C),0) -> 0 | I12: =IFERROR(SUMIF(Residential!$A:$A,$A12,Residential!D:D),0) -> 0 | J12: =IFERROR(SUMIF(Residential!$A:$A,$A12,Residential!E:E),0) -> 0 | K12: =IFERROR(SUMIF(Residential!$A:$A,$A12,Residential!F:F),0) -> 0 | L12: =IFERROR(SUMIF(Residential!$A:$A,$A12,Residential!G:G),0) -> 0 | M12: =IFERROR(SUMIF(Commercial!$A$3:$A$11,$A12,Commercial!Q$3:Q$11),0) -> 0 | N12: =IFERROR(SUMIF(Commercial!$A$3:$A$11,$A12,Commercial!V$3:V$11),0) -> 0 | O12: =IFERROR(SUMIF(Commercial!$A$3:$A$11,$A12,Commercial!W$3:W$11),0) -> 0 | P12: =IFERROR(SUMIF(Commercial!$A$3:$A$11,$A12,Commercial!AB$3:AB$11),0) -> 0 | Q12: =IFERROR(SUMIF(Commercial!$A$3:$A$11,$A12,Commercial!AC$3:AC$11),0) -> 0 | R12: =C12+H12+M12 -> 0 | S12: =D12+I12+N12 -> 0 | T12: =E12+J12+O12 -> 0 | U12: =F12+K12+P12 -> 0 | V12: =G12+L12+Q12 -> 0 | W12: =SUM(R12:V12) -> 0
